Workbook

Sheet Planilha
A1: Projeto | B1: Data | C1: Request | D1: Task | E1: Prioridade | F1: Retorno | G1: Módulo | H1: Tipo | I1: Usuário Projeto | J1: PO | K1: UUID PO | L1: Recurso | M1: UUID Recurso | N1: Épico | O1: Estória | P1: Tarefa | Q1: Etapa | R1: US | S1: Horas | T1: Pontos | U1: TicketE | V1: TicketS | W1: TicketT | X1: Jira | AC1: Alocadas | AD1: Tipo | AE1: =Parâmetros!$J3 -> BL | AF1: =Parâmetros!$J4 -> CR | AG1: =Parâmetros!$J5 -> MP | AH1: =Parâmetros!$J3 -> BL | AI1: =Parâmetros!$J4 -> CR | AJ1: =Parâmetros!$J5 -> MP | AK1: =Parâmetros!$J3 -> BL | AL1: =Parâmetros!$J4 -> CR | AM1: =Parâmetros!$J5 -> MP
A2: =UPPER(LEFT(I2, 3)) -> ENS | B2: 2026-09-08 | C2: 0 | D2: 0 | F2: 0 | G2: INTERFACE | H2: ALTERAÇÃO | I2: ensemble@thyssenkruppelevadores.com.br | J2: Giovani Perotto Mesquita | K2: =_xlfn.XLOOKUP(Planilha!$J2,Tabela9[Pessoas],Tabela9[UUID Jira]) -> 712020:8364b9cf-88a2-4399-9f86-fff7bed77ce2 | L2: Alexandre Trindade Pereira | M2: =_xlfn.XLOOKUP(Planilha!$L2,Tabela9[Pessoas],Tabela9[UUID Jira]) -> 712020:4a0c9d58-dbcd-4acf-b9ef-a74bff31dc8e | N2: Confeccionar logs para auditoria | O2: Confeccionar logs para auditoria | P2: Confeccionar logs para auditoria | Q2: Implementação | R2: Confeccionar logs para auditoria | S2: 10 | T2: =_xlfn.XLOOKUP(S2,Tabela4[Horas],Tabela4[Pontos],,1) -> 1 | U2: ENS-10640 | V2: ENS-10973 | W2: ENS-10974 | Y2: =HYPERLINK("https://tkebrasil.atlassian.net/browse/" & U2,U2) -> ENS-10640 | Z2: =HYPERLINK("https://tkebrasil.atlassian.net/browse/" & V2,V2) -> ENS-10973 | AA2: =HYPERLINK("https://tkebrasil.atlassian.net/browse/" & W2,W2) -> ENS-10974 | AC2: X | AD2: CR | AE2: =IF($AD2=AE$1,$U2) -> FALSE | AF2: =IF($AD2=AF$1,$U2) -> ENS-10640 | AG2: =IF($AD2=AG$1,$U2) -> FALSE | AH2: =IF($AD2=AH$1,$V2) -> FALSE | AI2: =IF($AD2=AI$1,$V2) -> ENS-10973 | AJ2: =IF($AD2=AJ$1,$V2) -> FALSE | AK2: =IF($AD2=AK$1,$W2) -> FALSE | AL2: =IF($AD2=AL$1,$W2) -> ENS-10974 | AM2: =IF($AD2=AM$1,$W2) -> FALSE | AN2: =IF(C2=0,"O","C") -> O | AO2: =IF(AND(AD2=Parâmetros!$J$3,AN2="C"),S2,0) -> 0 | AP2: =IF(AND(AD2=Parâmetros!$J$3,AN2="O"),S2,0) -> 0 | AQ2: =IF(AND(AD2=Parâmetros!$J$4,AN2="C"),S2,0) -> 0 | AR2: =IF(AND(AD2=Parâmetros!$J$4,AN2="O"),S2,0) -> 10 | AS2: =IF(AND(AD2=Parâmetros!$J$5,AN2="C"),S2,0) -> 0 | AT2: =IF(AND(AD2=Parâmetros!$J$5,AN2="O"),S2,0) -> 0
A3: =UPPER(LEFT(I3, 3)) -> ENS | B3: 2026-09-08 | C3: REQ0339905 | D3: SCTASK0581534 | F3: 0 | G3: INTERFACE | H3: NOVO DESENVOLVIMENTO | I3: ensemble@thyssenkruppelevadores.com.br | J3: Giovani Perotto Mesquita | K3: =_xlfn.XLOOKUP(Planilha!$J3,Tabela9[Pessoas],Tabela9[UUID Jira]) -> 712020:8364b9cf-88a2-4399-9f86-fff7bed77ce2 | L3: Tanise Sarmento | M3: =_xlfn.XLOOKUP(Planilha!$L3,Tabela9[Pessoas],Tabela9[UUID Jira]) -> 712020:4d5b2de5-c33f-44cb-8545-f17228d08baf | N3: PO - Menus Intec | O3: PO & GP - Menus Intec | P3: PO & GP - Menus Intec | Q3: Implementação | R3: PO & GP - Menus Intec | S3: 2 | T3: =_xlfn.XLOOKUP(S3,Tabela4[Horas],Tabela4[Pontos],,1) -> 0.5 | U3: ENS-10725 | V3: ENS-10975 | W3: ENS-10976 | Y3: =HYPERLINK("https://tkebrasil.atlassian.net/browse/" & U3,U3) -> ENS-10725 | Z3: =HYPERLINK("https://tkebrasil.atlassian.net/browse/" & V3,V3) -> ENS-10975 | AA3: =HYPERLINK("https://tkebrasil.atlassian.net/browse/" & W3,W3) -> ENS-10976 | AC3: X | AD3: MP | AE3: =IF($AD3=AE$1,$U3) -> FALSE | AF3: =IF($AD3=AF$1,$U3) -> FALSE | AG3: =IF($AD3=AG$1,$U3) -> ENS-10725 | AH3: =IF($AD3=AH$1,$V3) -> FALSE | AI3: =IF($AD3=AI$1,$V3) -> FALSE | AJ3: =IF($AD3=AJ$1,$V3) -> ENS-10975 | AK3: =IF($AD3=AK$1,$W3) -> FALSE | AL3: =IF($AD3=AL$1,$W3) -> FALSE | AM3: =IF($AD3=AM$1,$W3) -> ENS-10976 | AN3: =IF(C3=0,"O","C") -> C | AO3: =IF(AND(AD3=Parâmetros!$J$3,AN3="C"),S3,0) -> 0 | AP3: =IF(AND(AD3=Parâmetros!$J$3,AN3="O"),S3,0) -> 0 | AQ3: =IF(AND(AD3=Parâmetros!$J$4,AN3="C"),S3,0) -> 0 | AR3: =IF(AND(AD3=Parâmetros!$J$4,AN3="O"),S3,0) -> 0 | AS3: =IF(AND(AD3=Parâmetros!$J$5,AN3="C"),S3,0) -> 2 | AT3: =IF(AND(AD3=Parâmetros!$J$5,AN3="O"),S3,0) -> 0
A4: =UPPER(LEFT(I4, 3)) -> ENS | B4: 2026-09-08 | C4: 0 | D4: 0 | F4: 0 | G4: INTERFACE | H4: NOVO DESENVOLVIMENTO | I4: ensemble@thyssenkruppelevadores.com.br | J4: Giovani Perotto Mesquita | K4: =_xlfn.XLOOKUP(Planilha!$J4,Tabela9[Pessoas],Tabela9[UUID Jira]) -> 712020:8364b9cf-88a2-4399-9f86-fff7bed77ce2 | L4: Tanise Sarmento | M4: =_xlfn.XLOOKUP(Planilha!$L4,Tabela9[Pessoas],Tabela9[UUID Jira]) -> 712020:4d5b2de5-c33f-44cb-8545-f17228d08baf | N4: PO - Sprint | O4: PO - Sprint | P4: PO - Sprint | Q4: Implementação | R4: PO - Sprint | S4: 10 | T4: =_xlfn.XLOOKUP(S4,Tabela4[Horas],Tabela4[Pontos],,1) -> 1 | U4: ENS-10977 | V4: ENS-10978 | W4: ENS-10979 | AC4: X | AD4: CR
A5: =UPPER(LEFT(I5, 3)) -> ENS | B5: 2026-09-08 | C5: TKE China | D5: TKE China | F5: 0 | G5: INTERFACE | H5: NOVO DESENVOLVIMENTO | I5: ensemble@thyssenkruppelevadores.com.br | J5: Giovani Perotto Mesquita | K5: =_xlfn.XLOOKUP(Planilha!$J5,Tabela9[Pessoas],Tabela9[UUID Jira]) -> 712020:8364b9cf-88a2-4399-9f86-fff7bed77ce2 | L5: Tanise Sarmento | M5: =_xlfn.XLOOKUP(Planilha!$L5,Tabela9[Pessoas],Tabela9[UUID Jira]) -> 712020:4d5b2de5-c33f-44cb-8545-f17228d08baf | N5: PO - TKE China | O5: PO - TKE China | P5: PO - TKE China | Q5: Implementação | R5: TKE China | S5: 3 | T5: =_xlfn.XLOOKUP(S5,Tabela4[Horas],Tabela4[Pontos],,1) -> 0.5 | U5: ENS-10844 | V5: ENS-10980 | W5: ENS-10981 | Y5: =HYPERLINK("https://tkebrasil.atlassian.net/browse/" & U5,U5) -> ENS-10844 | Z5: =HYPERLINK("https://tkebrasil.atlassian.net/browse/" & V5,V5) -> ENS-10980 | AA5: =HYPERLINK("https://tkebrasil.atlassian.net/browse/" & W5,W5) -> ENS-10981 | AC5: X | AD5: CR | AE5: =IF($AD5=AE$1,$U5) -> FALSE | AF5: =IF($AD5=AF$1,$U5) -> ENS-10844 | AG5: =IF($AD5=AG$1,$U5) -> FALSE | AH5: =IF($AD5=AH$1,$V5) -> FALSE | AI5: =IF($AD5=AI$1,$V5) -> ENS-10980 | AJ5: =IF($AD5=AJ$1,$V5) -> FALSE | AK5: =IF($AD5=AK$1,$W5) -> FALSE | AL5: =IF($AD5=AL$1,$W5) -> ENS-10981 | AM5: =IF($AD5=AM$1,$W5) -> FALSE | AN5: =IF(C5=0,"O","C") -> C | AO5: =IF(AND(AD5=Parâmetros!$J$3,AN5="C"),S5,0) -> 0 | AP5: =IF(AND(AD5=Parâmetros!$J$3,AN5="O"),S5,0) -> 0 | AQ5: =IF(AND(AD5=Parâmetros!$J$4,AN5="C"),S5,0) -> 3 | AR5: =IF(AND(AD5=Parâmetros!$J$4,AN5="O"),S5,0) -> 0 | AS5: =IF(AND(AD5=Parâmetros!$J$5,AN5="C"),S5,0) -> 0 | AT5: =IF(AND(AD5=Parâmetros!$J$5,AN5="O"),S5,0) -> 0
A6: =UPPER(LEFT(I6, 3)) -> ENS | B6: 2026-09-08 | C6: 0 | D6: 0 | F6: 0 | G6: INTERFACE | H6: ALTERAÇÃO | I6: ensemble@thyssenkruppelevadores.com.br | J6: Giovani Perotto Mesquita | K6: =_xlfn.XLOOKUP(Planilha!$J6,Tabela9[Pessoas],Tabela9[UUID Jira]) -> 712020:8364b9cf-88a2-4399-9f86-fff7bed77ce2 | L6: Luis Henrique Petkovicz | M6: =_xlfn.XLOOKUP(Planilha!$L6,Tabela9[Pessoas],Tabela9[UUID Jira]) -> 557058:43e80a76-deba-4dd8-b64d-c7c8e99c6312 | N6: Atividades Administrativas | O6: Atividades Administrativas | P6: Atividades Administrativas | Q6: Implementação | R6: Atividades Administrativas | S6: 10 | T6: =_xlfn.XLOOKUP(S6,Tabela4[Horas],Tabela4[Pontos],,1) -> 1 | U6: ENS-8159 | V6: ENS-10982 | W6: ENS-10983 | Y6: =HYPERLINK("https://tkebrasil.atlassian.net/browse/" & U6,U6) -> ENS-8159 | Z6: =HYPERLINK("https://tkebrasil.atlassian.net/browse/" & V6,V6) -> ENS-10982 | AA6: =HYPERLINK("https://tkebrasil.atlassian.net/browse/" & W6,W6) -> ENS-10983 | AC6: X | AD6: BL | AE6: =IF($AD6=AE$1,$U6) -> ENS-8159 | AF6: =IF($AD6=AF$1,$U6) -> FALSE | AG6: =IF($AD6=AG$1,$U6) -> FALSE | AH6: =IF($AD6=AH$1,$V6) -> ENS-10982 | AI6: =IF($AD6=AI$1,$V6) -> FALSE | AJ6: =IF($AD6=AJ$1,$V6) -> FALSE | AK6: =IF($AD6=AK$1,$W6) -> ENS-10983 | AL6: =IF($AD6=AL$1,$W6) -> FALSE | AM6: =IF($AD6=AM$1,$W6) -> FALSE | AN6: =IF(C6=0,"O","C") -> O | AO6: =IF(AND(AD6=Parâmetros!$J$3,AN6="C"),S6,0) -> 0 | AP6: =IF(AND(AD6=Parâmetros!$J$3,AN6="O"),S6,0) -> 10 | AQ6: =IF(AND(AD6=Parâmetros!$J$4,AN6="C"),S6,0) -> 0 | AR6: =IF(AND(AD6=Parâmetros!$J$4,AN6="O"),S6,0) -> 0 | AS6: =IF(AND(AD6=Parâmetros!$J$5,AN6="C"),S6,0) -> 0 | AT6: =IF(AND(AD6=Parâmetros!$J$5,AN6="O"),S6,0) -> 0
A7: =UPPER(LEFT(I7, 3)) -> ENS | B7: 2026-09-08 | C7: REQ0377661 | D7: SCTASK0579990 | F7: 0 | G7: INTERFACE | H7: NOVO DESENVOLVIMENTO | I7: ensemble@thyssenkruppelevadores.com.br | J7: Giovani Perotto Mesquita | K7: =_xlfn.XLOOKUP(Planilha!$J7,Tabela9[Pessoas],Tabela9[UUID Jira]) -> 712020:8364b9cf-88a2-4399-9f86-fff7bed77ce2 | L7: Pablo Rocha | M7: =_xlfn.XLOOKUP(Planilha!$L7,Tabela9[Pessoas],Tabela9[UUID Jira]) -> 557058:004709f9-0a88-4979-a875-f58ca3985cf7 | N7: Integração de Margens entre GUS e E‑Sales | O7: Integração de Margens entre GUS e E‑Sales | P7: Integração de Margens entre GUS e E‑Sales | Q7: Análise Técnica | R7: 🌐 ÉPICO – Integração de Margens entre GUS e E‑Sales 🏷 Título do Épico Integração das Margens com e sem Desconto entre GUS e E‑Sales para Suporte ao Processo Comercial 🧾 Descrição Geral Este épico tem como objetivo estabelecer uma nova integração padronizada, confiável e automatizada entre os sistemas GUS e E‑Sales, permitindo o trânsito de informações de margem com desconto e margem sem desconto. A iniciativa busca eliminar atividades manuais, reduzir inconsistências, aumentar a velocidade das operações comerciais e aprimorar a tomada de decisão baseada em dados. PO Bruno Fuentes (Zallpy) Tiago Fogaça (PO) Victor Augusto Santos Marinho (Zallpy) 🎯 Objetivo Estratégico Garantir que o processo comercial opere com informações atualizadas, consistentes e rastreáveis. Apoiar decisões de precificação e propostas comerciais com dados íntegros. Reduzir riscos operacionais e retrabalho decorrentes de processos manuais. Aumentar eficiência e performance dos times comercial e financeiro. 📌 Escopo do Épico Inclui: Construção de interfaces de envio das margens com e sem desconto do GUS para o E‑Sales. Padronização de layouts, validações e regras de negócio. Implementação de logs, rastreabilidade, controle de erros e tratamento de rejeições. Testes funcionais, integrados, regressivos e de migração. Não inclui: Alterações no cálculo das margens. Modificações em regras de negócio internas do GUS ou do E‑Sales. Criação de dashboards ou relatórios derivados. 🗂 User Stories Associadas US – Enviar Margem com Desconto do GUS para o E‑Sales US – Enviar Margem sem Desconto do GUS para o E‑Sales (As histórias permanecem independentes para entrega incremental, mas agrupadas sob o mesmo objetivo macro.) 🧑‍💼 Stakeholders Envolvidos Área Comercial Área Financeira Equipe de Produto (IRIS ESB) Time responsável pelo GUS Time responsável pelo E‑Sales Time de Arquitetura e Governança de Integrações QA / Homologação 🚀 Benefícios Esperados Redução de erros manuais no processo de pricing. Aumento da confiabilidade das informações de margem. Otimização das operações comerciais (tempo de cotação). Aumento da precisão nas projeções financeiras e análises de margem. Melhor experiência para os usuários das áreas comercial e financeira. 🔄 Critérios de Aceitação do Épico O épico será considerado concluído quando: Ambas as interfaces (com e sem desconto) estiverem implementadas, testadas e homologadas. Processos de envio, rejeição, reprocessamento e logs estiverem implementados. Todos os ambientes (DEV, TQA e PRD) estiverem configurados e validados. Toda documentação funcional e técnica tiver sido atualizada. O time comercial confirmar que os dados estão disponíveis e íntegros no E‑Sales. 🧭 Cutover do Épico Comunicação às áreas usuárias sobre os novos fluxos. Treinamento rápido sobre leitura e impacto das margens no E‑Sales. Execução de testes fim a fim antes do go‑live. Reprocessamento inicial das margens para garantir baseline consistente. Monitoramento reforçado nas primeiras 72 horas pós-implantação. 📈 GUT Score do Épico Gravidade: 8 Urgência: 7 Tendência: 8 Total: 448 (Alta Prioridade Estratégica) | S7: 4 | T7: =_xlfn.XLOOKUP(S7,Tabela4[Horas],Tabela4[Pontos],,1) -> 0.5 | U7: ENS-8908 | V7: ENS-10984 | W7: ENS-10985 | Y7: =HYPERLINK("https://tkebrasil.atlassian.net/browse/" & U7,U7) -> ENS-8908 | Z7: =HYPERLINK("https://tkebrasil.atlassian.net/browse/" & V7,V7) -> ENS-10984 | AA7: =HYPERLINK("https://tkebrasil.atlassian.net/browse/" & W7,W7) -> ENS-10985 | AC7: X | AD7: BL | AE7: =IF($AD7=AE$1,$U7) -> ENS-8908 | AF7: =IF($AD7=AF$1,$U7) -> FALSE | AG7: =IF($AD7=AG$1,$U7) -> FALSE | AH7: =IF($AD7=AH$1,$V7) -> ENS-10984 | AI7: =IF($AD7=AI$1,$V7) -> FALSE | AJ7: =IF($AD7=AJ$1,$V7) -> FALSE | AK7: =IF($AD7=AK$1,$W7) -> ENS-10985 | AL7: =IF($AD7=AL$1,$W7) -> FALSE | AM7: =IF($AD7=AM$1,$W7) -> FALSE | AN7: =IF(C7=0,"O","C") -> C | AO7: =IF(AND(AD7=Parâmetros!$J$3,AN7="C"),S7,0) -> 4 | AP7: =IF(AND(AD7=Parâmetros!$J$3,AN7="O"),S7,0) -> 0 | AQ7: =IF(AND(AD7=Parâmetros!$J$4,AN7="C"),S7,0) -> 0 | AR7: =IF(AND(AD7=Parâmetros!$J$4,AN7="O"),S7,0) -> 0 | AS7: =IF(AND(AD7=Parâmetros!$J$5,AN7="C"),S7,0) -> 0 | AT7: =IF(AND(AD7=Parâmetros!$J$5,AN7="O"),S7,0) -> 0
A8: =UPPER(LEFT(I8, 3)) -> ENS | B8: 2026-09-08 | C8: 0 | D8: 0 | F8: 0 | G8: INTERFACE | H8: NOVO DESENVOLVIMENTO | I8: ensemble@thyssenkruppelevadores.com.br | J8: Giovani Perotto Mesquita | K8: =_xlfn.XLOOKUP(Planilha!$J8,Tabela9[Pessoas],Tabela9[UUID Jira]) -> 712020:8364b9cf-88a2-4399-9f86-fff7bed77ce2 | L8: Luis Henrique Petkovicz | M8: =_xlfn.XLOOKUP(Planilha!$L8,Tabela9[Pessoas],Tabela9[UUID Jira]) -> 557058:43e80a76-deba-4dd8-b64d-c7c8e99c6312 | N8: Alterar logs do IRIS para tabela federada | O8: Alterar logs do IRIS para tabela federada 1 | P8: Alterar logs do IRIS para tabela federada 1 | Q8: Implementação | R8: ✅ User Story 1 — Persistência Estruturada de Logs de Auditoria 🧾 Requisito Definido Implementar mecanismo de persistência estruturada para logs de auditoria do middleware, garantindo rastreabilidade, governança operacional e suporte aos processos de ITSM (ITIL). Os registros deverão contemplar, no mínimo, os seguintes atributos: Status: classificação do registro conforme análise do AMS (Application Management Services), indicando o estado operacional, tratamento ou encaminhamento do evento; UC – Caso de Uso: identificação do uso de caso ou fluxo de negócio associado ao registro, viabilizando rastreabilidade ponta a ponta para fins de auditoria e investigação; Criticidade: nível de impacto do evento (baixa, média ou alta), suportando priorização operacional e gestão de incidentes; Incidente/Requisição: referência ao incidente ou requisição registrada no sistema de ITSM, quando houver necessidade de abertura de ticket, assegurando integração com os processos de Incident e Request Management. Essa persistência deverá permitir auditorias técnicas e funcionais, apoiar análises de causa raiz, além de atender requisitos de compliance, observabilidade e melhoria contínua do ambiente de integração. 🧑‍💼 Contato Giovani Mesquita – Product Owner AMS (Application Management Services) Equipe de Middleware / Integração Governança de TI / ITSM 📖 Título da User Story Como Product Owner, quero que o middleware persista logs de auditoria de forma estruturada, para que seja possível garantir rastreabilidade, governança operacional e suporte aos processos de ITSM. 📊 Priorização Alta Justificativa: Alto valor para compliance, auditoria e governança Impacto direto na operação e no suporte (Incident/Request Management) Necessário para análise de causa raiz e melhoria contínua Dependência para processos operacionais e auditorias futuras 🔍 Processo Atual (AS IS) Atualmente, o middleware não possui um mecanismo estruturado e persistente para registro de logs de auditoria, dificultando a rastreabilidade de eventos, investigações operacionais, auditorias técnicas e integração com processos de ITSM. 🚀 Processo Futuro (TO BE) O middleware passará a registrar e persistir logs de auditoria de forma estruturada, contendo informações essenciais para análise operacional, auditoria e governança, permitindo integração com processos de Incident e Request Management. 🎯 Objetivo da Mudança Garantir rastreabilidade ponta a ponta dos eventos do middleware Apoiar auditorias técnicas e funcionais Facilitar análises de causa raiz Suportar compliance, observabilidade e melhoria contínua Integrar os eventos do middleware aos processos de ITSM ❌ Fora de Escopo Criação ou customização do sistema de ITSM Dashboards analíticos ou relatórios avançados Automação de abertura de tickets Retenção histórica além do definido pelo middleware ✅ Critérios de Aceitação (BDD) Cenário 1 – Persistência correta dos logs Dado que um evento ocorre no middleware Quando o log de auditoria é registrado Então o registro deve ser persistido contendo Status, Caso de Uso, Criticidade e referência a Incidente/Requisição (quando aplicável) Cenário 2 – Registro de criticidade Dado um evento com impacto operacional Quando o log é persistido Então a criticidade deve ser registrada como baixa, média ou alta Cenário 3 – Integração com ITSM Dado que houve necessidade de abertura de ticket Quando o log for persistido Então o campo Incidente/Requisição deve conter a referência correspondente 🧪 Cenários de Teste de Validação Pré-condições Middleware em funcionamento Mecanismo de persistência disponível Passos Gerar um evento no middleware Informar Caso de Uso e Criticidade Associar um ticket de Incidente/Requisição (quando aplicável) Resultados Esperados Log persistido corretamente Campos preenchidos conforme definido Registro disponível para auditoria e análise ❌ Cenários de Teste de Rejeição Persistência do log sem Status Persistência do log sem identificação do Caso de Uso Registro de criticidade fora dos valores permitidos (baixa, média, alta) Registro inconsistente entre evento e referência de Incidente/Requisição 🔄 Cenários de Teste de Regressão Execução de fluxos existentes do middleware sem impacto de performance perceptível Processamento normal das integrações após ativação da persistência de logs Ausência de falhas ou indisponibilidade causada pelo novo mecanismo 🧭 Sugestão de Cutover Comunicação às equipes de AMS e Governança sobre o novo padrão de logs Validação em ambiente produtivo com eventos controlados Monitoramento inicial pós-implantação Disponibilização de evidências para auditoria | S8: 2 | T8: =_xlfn.XLOOKUP(S8,Tabela4[Horas],Tabela4[Pontos],,1) -> 0.5 | U8: ENS-9944 | V8: ENS-10986 | W8: ENS-10987 | Y8: =HYPERLINK("https://tkebrasil.atlassian.net/browse/" & U8,U8) -> ENS-9944 | Z8: =HYPERLINK("https://tkebrasil.atlassian.net/browse/" & V8,V8) -> ENS-10986 | AA8: =HYPERLINK("https://tkebrasil.atlassian.net/browse/" & W8,W8) -> ENS-10987 | AC8: X | AD8: BL | AE8: =IF($AD8=AE$1,$U8) -> ENS-9944 | AF8: =IF($AD8=AF$1,$U8) -> FALSE | AG8: =IF($AD8=AG$1,$U8) -> FALSE | AH8: =IF($AD8=AH$1,$V8) -> ENS-10986 | AI8: =IF($AD8=AI$1,$V8) -> FALSE | AJ8: =IF($AD8=AJ$1,$V8) -> FALSE | AK8: =IF($AD8=AK$1,$W8) -> ENS-10987 | AL8: =IF($AD8=AL$1,$W8) -> FALSE | AM8: =IF($AD8=AM$1,$W8) -> FALSE | AN8: =IF(C8=0,"O","C") -> O | AO8: =IF(AND(AD8=Parâmetros!$J$3,AN8="C"),S8,0) -> 0 | AP8: =IF(AND(AD8=Parâmetros!$J$3,AN8="O"),S8,0) -> 2 | AQ8: =IF(AND(AD8=Parâmetros!$J$4,AN8="C"),S8,0) -> 0 | AR8: =IF(AND(AD8=Parâmetros!$J$4,AN8="O"),S8,0) -> 0 | AS8: =IF(AND(AD8=Parâmetros!$J$5,AN8="C"),S8,0) -> 0 | AT8: =IF(AND(AD8=Parâmetros!$J$5,AN8="O"),S8,0) -> 0
A9: =UPPER(LEFT(I9, 3)) -> ENS | B9: 2026-09-08 | C9: 0 | D9: 0 | F9: 0 | G9: INTERFACE | H9: NOVO DESENVOLVIMENTO | I9: ensemble@thyssenkruppelevadores.com.br | J9: Giovani Perotto Mesquita | K9: =_xlfn.XLOOKUP(Planilha!$J9,Tabela9[Pessoas],Tabela9[UUID Jira]) -> 712020:8364b9cf-88a2-4399-9f86-fff7bed77ce2 | L9: Regina Albanus | M9: =_xlfn.XLOOKUP(Planilha!$L9,Tabela9[Pessoas],Tabela9[UUID Jira]) -> 557058:330c824e-66ab-4df0-b7eb-8ddf9d578a4e | N9: Alterar logs do IRIS para tabela federada | O9: Alterar logs do IRIS para tabela federada 2 | P9: Alterar logs do IRIS para tabela federada 2 | Q9: Implementação | R9: ✅ User Story 1 — Persistência Estruturada de Logs de Auditoria 🧾 Requisito Definido Implementar mecanismo de persistência estruturada para logs de auditoria do middleware, garantindo rastreabilidade, governança operacional e suporte aos processos de ITSM (ITIL). Os registros deverão contemplar, no mínimo, os seguintes atributos: Status: classificação do registro conforme análise do AMS (Application Management Services), indicando o estado operacional, tratamento ou encaminhamento do evento; UC – Caso de Uso: identificação do uso de caso ou fluxo de negócio associado ao registro, viabilizando rastreabilidade ponta a ponta para fins de auditoria e investigação; Criticidade: nível de impacto do evento (baixa, média ou alta), suportando priorização operacional e gestão de incidentes; Incidente/Requisição: referência ao incidente ou requisição registrada no sistema de ITSM, quando houver necessidade de abertura de ticket, assegurando integração com os processos de Incident e Request Management. Essa persistência deverá permitir auditorias técnicas e funcionais, apoiar análises de causa raiz, além de atender requisitos de compliance, observabilidade e melhoria contínua do ambiente de integração. 🧑‍💼 Contato Giovani Mesquita – Product Owner AMS (Application Management Services) Equipe de Middleware / Integração Governança de TI / ITSM 📖 Título da User Story Como Product Owner, quero que o middleware persista logs de auditoria de forma estruturada, para que seja possível garantir rastreabilidade, governança operacional e suporte aos processos de ITSM. 📊 Priorização Alta Justificativa: Alto valor para compliance, auditoria e governança Impacto direto na operação e no suporte (Incident/Request Management) Necessário para análise de causa raiz e melhoria contínua Dependência para processos operacionais e auditorias futuras 🔍 Processo Atual (AS IS) Atualmente, o middleware não possui um mecanismo estruturado e persistente para registro de logs de auditoria, dificultando a rastreabilidade de eventos, investigações operacionais, auditorias técnicas e integração com processos de ITSM. 🚀 Processo Futuro (TO BE) O middleware passará a registrar e persistir logs de auditoria de forma estruturada, contendo informações essenciais para análise operacional, auditoria e governança, permitindo integração com processos de Incident e Request Management. 🎯 Objetivo da Mudança Garantir rastreabilidade ponta a ponta dos eventos do middleware Apoiar auditorias técnicas e funcionais Facilitar análises de causa raiz Suportar compliance, observabilidade e melhoria contínua Integrar os eventos do middleware aos processos de ITSM ❌ Fora de Escopo Criação ou customização do sistema de ITSM Dashboards analíticos ou relatórios avançados Automação de abertura de tickets Retenção histórica além do definido pelo middleware ✅ Critérios de Aceitação (BDD) Cenário 1 – Persistência correta dos logs Dado que um evento ocorre no middleware Quando o log de auditoria é registrado Então o registro deve ser persistido contendo Status, Caso de Uso, Criticidade e referência a Incidente/Requisição (quando aplicável) Cenário 2 – Registro de criticidade Dado um evento com impacto operacional Quando o log é persistido Então a criticidade deve ser registrada como baixa, média ou alta Cenário 3 – Integração com ITSM Dado que houve necessidade de abertura de ticket Quando o log for persistido Então o campo Incidente/Requisição deve conter a referência correspondente 🧪 Cenários de Teste de Validação Pré-condições Middleware em funcionamento Mecanismo de persistência disponível Passos Gerar um evento no middleware Informar Caso de Uso e Criticidade Associar um ticket de Incidente/Requisição (quando aplicável) Resultados Esperados Log persistido corretamente Campos preenchidos conforme definido Registro disponível para auditoria e análise ❌ Cenários de Teste de Rejeição Persistência do log sem Status Persistência do log sem identificação do Caso de Uso Registro de criticidade fora dos valores permitidos (baixa, média, alta) Registro inconsistente entre evento e referência de Incidente/Requisição 🔄 Cenários de Teste de Regressão Execução de fluxos existentes do middleware sem impacto de performance perceptível Processamento normal das integrações após ativação da persistência de logs Ausência de falhas ou indisponibilidade causada pelo novo mecanismo 🧭 Sugestão de Cutover Comunicação às equipes de AMS e Governança sobre o novo padrão de logs Validação em ambiente produtivo com eventos controlados Monitoramento inicial pós-implantação Disponibilização de evidências para auditoria | S9: 2 | T9: =_xlfn.XLOOKUP(S9,Tabela4[Horas],Tabela4[Pontos],,1) -> 0.5 | U9: ENS-9944 | V9: ENS-10988 | W9: ENS-10989 | Y9: =HYPERLINK("https://tkebrasil.atlassian.net/browse/" & U9,U9) -> ENS-9944 | Z9: =HYPERLINK("https://tkebrasil.atlassian.net/browse/" & V9,V9) -> ENS-10988 | AA9: =HYPERLINK("https://tkebrasil.atlassian.net/browse/" & W9,W9) -> ENS-10989 | AC9: X | AD9: BL | AE9: =IF($AD9=AE$1,$U9) -> ENS-9944 | AF9: =IF($AD9=AF$1,$U9) -> FALSE | AG9: =IF($AD9=AG$1,$U9) -> FALSE | AH9: =IF($AD9=AH$1,$V9) -> ENS-10988 | AI9: =IF($AD9=AI$1,$V9) -> FALSE | AJ9: =IF($AD9=AJ$1,$V9) -> FALSE | AK9: =IF($AD9=AK$1,$W9) -> ENS-10989 | AL9: =IF($AD9=AL$1,$W9) -> FALSE | AM9: =IF($AD9=AM$1,$W9) -> FALSE | AN9: =IF(C9=0,"O","C") -> O | AO9: =IF(AND(AD9=Parâmetros!$J$3,AN9="C"),S9,0) -> 0 | AP9: =IF(AND(AD9=Parâmetros!$J$3,AN9="O"),S9,0) -> 2 | AQ9: =IF(AND(AD9=Parâmetros!$J$4,AN9="C"),S9,0) -> 0 | AR9: =IF(AND(AD9=Parâmetros!$J$4,AN9="O"),S9,0) -> 0 | AS9: =IF(AND(AD9=Parâmetros!$J$5,AN9="C"),S9,0) -> 0 | AT9: =IF(AND(AD9=Parâmetros!$J$5,AN9="O"),S9,0) -> 0
A10: =UPPER(LEFT(I10, 3)) -> ENS | B10: 2026-09-08 | C10: 0 | D10: 0 | F10: 0 | G10: INTERFACE | H10: NOVO DESENVOLVIMENTO | I10: ensemble@thyssenkruppelevadores.com.br | J10: Giovani Perotto Mesquita | K10: =_xlfn.XLOOKUP(Planilha!$J10,Tabela9[Pessoas],Tabela9[UUID Jira]) -> 712020:8364b9cf-88a2-4399-9f86-fff7bed77ce2 | L10: Pablo Rocha | M10: =_xlfn.XLOOKUP(Planilha!$L10,Tabela9[Pessoas],Tabela9[UUID Jira]) -> 557058:004709f9-0a88-4979-a875-f58ca3985cf7 | N10: Alterar logs do IRIS para tabela federada | O10: Alterar logs do IRIS para tabela federada 3 | P10: Alterar logs do IRIS para tabela federada 3 | Q10: Implementação | R10: ✅ User Story 1 — Persistência Estruturada de Logs de Auditoria 🧾 Requisito Definido Implementar mecanismo de persistência estruturada para logs de auditoria do middleware, garantindo rastreabilidade, governança operacional e suporte aos processos de ITSM (ITIL). Os registros deverão contemplar, no mínimo, os seguintes atributos: Status: classificação do registro conforme análise do AMS (Application Management Services), indicando o estado operacional, tratamento ou encaminhamento do evento; UC – Caso de Uso: identificação do uso de caso ou fluxo de negócio associado ao registro, viabilizando rastreabilidade ponta a ponta para fins de auditoria e investigação; Criticidade: nível de impacto do evento (baixa, média ou alta), suportando priorização operacional e gestão de incidentes; Incidente/Requisição: referência ao incidente ou requisição registrada no sistema de ITSM, quando houver necessidade de abertura de ticket, assegurando integração com os processos de Incident e Request Management. Essa persistência deverá permitir auditorias técnicas e funcionais, apoiar análises de causa raiz, além de atender requisitos de compliance, observabilidade e melhoria contínua do ambiente de integração. 🧑‍💼 Contato Giovani Mesquita – Product Owner AMS (Application Management Services) Equipe de Middleware / Integração Governança de TI / ITSM 📖 Título da User Story Como Product Owner, quero que o middleware persista logs de auditoria de forma estruturada, para que seja possível garantir rastreabilidade, governança operacional e suporte aos processos de ITSM. 📊 Priorização Alta Justificativa: Alto valor para compliance, auditoria e governança Impacto direto na operação e no suporte (Incident/Request Management) Necessário para análise de causa raiz e melhoria contínua Dependência para processos operacionais e auditorias futuras 🔍 Processo Atual (AS IS) Atualmente, o middleware não possui um mecanismo estruturado e persistente para registro de logs de auditoria, dificultando a rastreabilidade de eventos, investigações operacionais, auditorias técnicas e integração com processos de ITSM. 🚀 Processo Futuro (TO BE) O middleware passará a registrar e persistir logs de auditoria de forma estruturada, contendo informações essenciais para análise operacional, auditoria e governança, permitindo integração com processos de Incident e Request Management. 🎯 Objetivo da Mudança Garantir rastreabilidade ponta a ponta dos eventos do middleware Apoiar auditorias técnicas e funcionais Facilitar análises de causa raiz Suportar compliance, observabilidade e melhoria contínua Integrar os eventos do middleware aos processos de ITSM ❌ Fora de Escopo Criação ou customização do sistema de ITSM Dashboards analíticos ou relatórios avançados Automação de abertura de tickets Retenção histórica além do definido pelo middleware ✅ Critérios de Aceitação (BDD) Cenário 1 – Persistência correta dos logs Dado que um evento ocorre no middleware Quando o log de auditoria é registrado Então o registro deve ser persistido contendo Status, Caso de Uso, Criticidade e referência a Incidente/Requisição (quando aplicável) Cenário 2 – Registro de criticidade Dado um evento com impacto operacional Quando o log é persistido Então a criticidade deve ser registrada como baixa, média ou alta Cenário 3 – Integração com ITSM Dado que houve necessidade de abertura de ticket Quando o log for persistido Então o campo Incidente/Requisição deve conter a referência correspondente 🧪 Cenários de Teste de Validação Pré-condições Middleware em funcionamento Mecanismo de persistência disponível Passos Gerar um evento no middleware Informar Caso de Uso e Criticidade Associar um ticket de Incidente/Requisição (quando aplicável) Resultados Esperados Log persistido corretamente Campos preenchidos conforme definido Registro disponível para auditoria e análise ❌ Cenários de Teste de Rejeição Persistência do log sem Status Persistência do log sem identificação do Caso de Uso Registro de criticidade fora dos valores permitidos (baixa, média, alta) Registro inconsistente entre evento e referência de Incidente/Requisição 🔄 Cenários de Teste de Regressão Execução de fluxos existentes do middleware sem impacto de performance perceptível Processamento normal das integrações após ativação da persistência de logs Ausência de falhas ou indisponibilidade causada pelo novo mecanismo 🧭 Sugestão de Cutover Comunicação às equipes de AMS e Governança sobre o novo padrão de logs Validação em ambiente produtivo com eventos controlados Monitoramento inicial pós-implantação Disponibilização de evidências para auditoria | S10: 10 | T10: =_xlfn.XLOOKUP(S10,Tabela4[Horas],Tabela4[Pontos],,1) -> 1 | U10: ENS-9944 | V10: ENS-10990 | W10: ENS-10991 | Y10: =HYPERLINK("https://tkebrasil.atlassian.net/browse/" & U10,U10) -> ENS-9944 | Z10: =HYPERLINK("https://tkebrasil.atlassian.net/browse/" & V10,V10) -> ENS-10990 | AA10: =HYPERLINK("https://tkebrasil.atlassian.net/browse/" & W10,W10) -> ENS-10991 | AC10: X | AD10: BL | AE10: =IF($AD10=AE$1,$U10) -> ENS-9944 | AF10: =IF($AD10=AF$1,$U10) -> FALSE | AG10: =IF($AD10=AG$1,$U10) -> FALSE | AH10: =IF($AD10=AH$1,$V10) -> ENS-10990 | AI10: =IF($AD10=AI$1,$V10) -> FALSE | AJ10: =IF($AD10=AJ$1,$V10) -> FALSE | AK10: =IF($AD10=AK$1,$W10) -> ENS-10991 | AL10: =IF($AD10=AL$1,$W10) -> FALSE | AM10: =IF($AD10=AM$1,$W10) -> FALSE | AN10: =IF(C10=0,"O","C") -> O | AO10: =IF(AND(AD10=Parâmetros!$J$3,AN10="C"),S10,0) -> 0 | AP10: =IF(AND(AD10=Parâmetros!$J$3,AN10="O"),S10,0) -> 10 | AQ10: =IF(AND(AD10=Parâmetros!$J$4,AN10="C"),S10,0) -> 0 | AR10: =IF(AND(AD10=Parâmetros!$J$4,AN10="O"),S10,0) -> 0 | AS10: =IF(AND(AD10=Parâmetros!$J$5,AN10="C"),S10,0) -> 0 | AT10: =IF(AND(AD10=Parâmetros!$J$5,AN10="O"),S10,0) -> 0
A11: =UPPER(LEFT(I11, 3)) -> ENS | B11: 2026-09-08 | C11: CR AP Summary | D11: CR AP Summary | F11: 0 | G11: INTERFACE | H11: NOVO DESENVOLVIMENTO | I11: ensemble@thyssenkruppelevadores.com.br | J11: Giovani Perotto Mesquita | K11: =_xlfn.XLOOKUP(Planilha!$J11,Tabela9[Pessoas],Tabela9[UUID Jira]) -> 712020:8364b9cf-88a2-4399-9f86-fff7bed77ce2 | L11: Regina Albanus | M11: =_xlfn.XLOOKUP(Planilha!$L11,Tabela9[Pessoas],Tabela9[UUID Jira]) -> 557058:330c824e-66ab-4df0-b7eb-8ddf9d578a4e | N11: Alteração da interface Sincrona para Assincrona do AP Summary | O11: Alteração da interface Sincrona para Assincrona do AP Summary | P11: Alteração da interface Sincrona para Assincrona do AP Summary | Q11: Execução de Testes | R11: Conforme CR do projeto AP Summary | S11: 2 | T11: =_xlfn.XLOOKUP(S11,Tabela4[Horas],Tabela4[Pontos],,1) -> 0.5 | U11: ENS-9951 | V11: ENS-10992 | W11: ENS-10993 | Y11: =HYPERLINK("https://tkebrasil.atlassian.net/browse/" & U11,U11) -> ENS-9951 | Z11: =HYPERLINK("https://tkebrasil.atlassian.net/browse/" & V11,V11) -> ENS-10992 | AA11: =HYPERLINK("https://tkebrasil.atlassian.net/browse/" & W11,W11) -> ENS-10993 | AC11: X | AD11: BL | AE11: =IF($AD11=AE$1,$U11) -> ENS-9951 | AF11: =IF($AD11=AF$1,$U11) -> FALSE | AG11: =IF($AD11=AG$1,$U11) -> FALSE | AH11: =IF($AD11=AH$1,$V11) -> ENS-10992 | AI11: =IF($AD11=AI$1,$V11) -> FALSE | AJ11: =IF($AD11=AJ$1,$V11) -> FALSE | AK11: =IF($AD11=AK$1,$W11) -> ENS-10993 | AL11: =IF($AD11=AL$1,$W11) -> FALSE | AM11: =IF($AD11=AM$1,$W11) -> FALSE | AN11: =IF(C11=0,"O","C") -> C | AO11: =IF(AND(AD11=Parâmetros!$J$3,AN11="C"),S11,0) -> 2 | AP11: =IF(AND(AD11=Parâmetros!$J$3,AN11="O"),S11,0) -> 0 | AQ11: =IF(AND(AD11=Parâmetros!$J$4,AN11="C"),S11,0) -> 0 | AR11: =IF(AND(AD11=Parâmetros!$J$4,AN11="O"),S11,0) -> 0 | AS11: =IF(AND(AD11=Parâmetros!$J$5,AN11="C"),S11,0) -> 0 | AT11: =IF(AND(AD11=Parâmetros!$J$5,AN11="O"),S11,0) -> 0
A12: =UPPER(LEFT(I12, 3)) -> ENS | B12: 2026-09-08 | C12: REQ0505088 | D12: SCTASK0704281 | F12: 0 | G12: INTERFACE | H12: ALTERAÇÃO | I12: ensemble@thyssenkruppelevadores.com.br | J12: Giovani Perotto Mesquita | K12: =_xlfn.XLOOKUP(Planilha!$J12,Tabela9[Pessoas],Tabela9[UUID Jira]) -> 712020:8364b9cf-88a2-4399-9f86-fff7bed77ce2 | L12: Luiz Felipe Brandão da Silva | M12: =_xlfn.XLOOKUP(Planilha!$L12,Tabela9[Pessoas],Tabela9[UUID Jira]) -> 6245e14af6a26900695d5c1c | N12: Alterar na interface PosicaoFinanceira.ContratosContatos para que tivermos erro interno do IRIS, mandar uma mensagem | O12: Alterar na interface PosicaoFinanceira.ContratosContatos para que tivermos erro interno do IRIS, mandar uma mensagem | P12: Alterar na interface PosicaoFinanceira.ContratosContatos para que tivermos erro interno do IRIS, mandar uma mensagem | Q12: Execução de Testes | R12: Alterar na interface PosicaoFinanceira.ContratosContatos para que tivermos erro interno do IRIS, mandar uma mensagem. PO - Marco Gross | S12: 2 | T12: =_xlfn.XLOOKUP(S12,Tabela4[Horas],Tabela4[Pontos],,1) -> 0.5 | U12: ENS-9954 | V12: ENS-10994 | W12: ENS-10995 | Y12: =HYPERLINK("https://tkebrasil.atlassian.net/browse/" & U12,U12) -> ENS-9954 | Z12: =HYPERLINK("https://tkebrasil.atlassian.net/browse/" & V12,V12) -> ENS-10994 | AA12: =HYPERLINK("https://tkebrasil.atlassian.net/browse/" & W12,W12) -> ENS-10995 | AC12: X | AD12: BL | AE12: =IF($AD12=AE$1,$U12) -> ENS-9954 | AF12: =IF($AD12=AF$1,$U12) -> FALSE | AG12: =IF($AD12=AG$1,$U12) -> FALSE | AH12: =IF($AD12=AH$1,$V12) -> ENS-10994 | AI12: =IF($AD12=AI$1,$V12) -> FALSE | AJ12: =IF($AD12=AJ$1,$V12) -> FALSE | AK12: =IF($AD12=AK$1,$W12) -> ENS-10995 | AL12: =IF($AD12=AL$1,$W12) -> FALSE | AM12: =IF($AD12=AM$1,$W12) -> FALSE | AN12: =IF(C12=0,"O","C") -> C | AO12: =IF(AND(AD12=Parâmetros!$J$3,AN12="C"),S12,0) -> 2 | AP12: =IF(AND(AD12=Parâmetros!$J$3,AN12="O"),S12,0) -> 0 | AQ12: =IF(AND(AD12=Parâmetros!$J$4,AN12="C"),S12,0) -> 0 | AR12: =IF(AND(AD12=Parâmetros!$J$4,AN12="O"),S12,0) -> 0 | AS12: =IF(AND(AD12=Parâmetros!$J$5,AN12="C"),S12,0) -> 0 | AT12: =IF(AND(AD12=Parâmetros!$J$5,AN12="O"),S12,0) -> 0
A13: =UPPER(LEFT(I13, 3)) -> ENS | B13: 2026-09-08 | C13: REQ0396346 | D13: SCTASK0592786 | F13: 0 | G13: INTERFACE | H13: ALTERAÇÃO | I13: ensemble@thyssenkruppelevadores.com.br | J13: Giovani Perotto Mesquita | K13: =_xlfn.XLOOKUP(Planilha!$J13,Tabela9[Pessoas],Tabela9[UUID Jira]) -> 712020:8364b9cf-88a2-4399-9f86-fff7bed77ce2 | L13: Pablo Rocha | M13: =_xlfn.XLOOKUP(Planilha!$L13,Tabela9[Pessoas],Tabela9[UUID Jira]) -> 557058:004709f9-0a88-4979-a875-f58ca3985cf7 | N13: Criar e disponibilizar um novo campo denominado “Preço Max” na transação ZV75 do SAP, garantindo que o valor de reajuste em contratos PRICING seja enviado de forma segregada (Preço de Manutenção e Preço Max) para permitir o correto tratamento no GUS e alinhamento das linhas CMAX no SAP, por meio do fluxo de integração SAP → IRIS → GUS. | O13: Criar e disponibilizar um novo campo denominado “Preço Max” na transação ZV75 do SAP, garantindo que o valor de reajuste em contratos PRICING seja enviado de forma segregada (Preço de Manutenção e Preço Max) para permitir o correto tratamento no GUS e alinhamento das linhas CMAX no SAP, por meio do fluxo de integração SAP → IRIS → GUS. | P13: Criar e disponibilizar um novo campo denominado “Preço Max” na transação ZV75 do SAP, garantindo que o valor de reajuste em contratos PRICING seja enviado de forma segregada (Preço de Manutenção e Preço Max) para permitir o correto tratamento no GUS e alinhamento das linhas CMAX no SAP, por meio do fluxo de integração SAP → IRIS → GUS. | Q13: Execução de Testes | R13: 🧾 Defined Requirement Criar e disponibilizar um novo campo denominado “Preço Max” na transação ZV75 do SAP, garantindo que o valor de reajuste em contratos PRICING seja enviado de forma segregada (Preço de Manutenção e Preço Max) para permitir o correto tratamento no GUS e alinhamento das linhas CMAX no SAP, por meio do fluxo de integração SAP → IRIS → GUS. 🧑‍💼 Contact João Mateus – Product Owner SAP Stephanie - Product Owner GUS Equipe SAP Equipe IRIS Equipe GUS Gabriel Kramer – Stakeholder (reunião prévia) Fernanda Gelatti – Stakeholder (reunião prévia) 📖 User Story Title As a Analista de Negócio, I want que o SAP envie separadamente os valores de Preço de Manutenção e Preço Max, so that os contratos PRICING sejam ajustados corretamente no GUS e alinhem as linhas CMAX no SAP. 📊 Prioritization Priority: High Justificativa: Business value: Permite cálculo correto de reajustes contratuais PRICING. Impacto: Impede inconsistências financeiras e retrabalho manual. Urgência: Situação atual bloqueia ajustes corretos no GUS. Dependências: Integração direta entre SAP, IRIS e GUS. 🔍 Current Process (AS IS) Atualmente, o SAP envia um único valor de reajuste, sem separação entre Preço de Manutenção e Preço Max. Esse modelo impossibilita: Ajuste correto das tabelas no GUS Alinhamento das linhas CMAX no SAP 🚀 Future Process (TO BE) O SAP passa a disponibilizar um novo campo “Preço Max” na ZV75, enviando: Preço de Manutenção Preço Max O IRIS atualiza o arquivo de integração e o GUS recebe os valores de forma segregada, aplicando corretamente os ajustes conforme a regra de negócio. 🎯 Change Objective Garantir conformidade contratual e correto tratamento financeiro dos contratos PRICING, eliminando inconsistências e dependência de ajustes manuais. ❌ Out of Scope Alterações em tipos contratuais que não sejam PRICING Revisão de regras de cálculo no GUS além do consumo do novo campo Mudanças retroativas em contratos já encerrados ✅ Acceptance Criteria (BDD) Scenario 1 – Envio correto dos valores segregados Given que existe um contrato do tipo PRICING no SAP When o reajuste contratual for processado Then o SAP deve enviar separadamente os campos “Preço de Manutenção” e “Preço Max” para o IRIS And o GUS deve receber ambos os valores de forma estruturada Scenario 2 – Campo obrigatório Given um contrato PRICING When o campo “Preço Max” não estiver preenchido Then o contrato não deve ser enviado para integração 🧪 Validation Test Scenarios Cenário 1 – Fluxo completo SAP → IRIS → GUS Precondições: Contrato PRICING ativo no SAP Passos: Informar Preço de Manutenção Informar Preço Max na ZV75 Executar integração Resultado Esperado: Ambos os valores recebidos corretamente no GUS ❌ Rejection Test Scenarios Cenário – Envio de valor único Situação: SAP envia apenas um valor consolidado Resultado Esperado: Integração rejeitada ou sinalizada como incorreta GUS não aplica ajuste 🔄 Regression Test Scenarios Cenário – Contratos não PRICING Verificação: Contratos de outros tipos continuam funcionando sem impacto Resultado Esperado: Nenhuma alteração nos fluxos existentes 🧭 Cutover Suggestion Comunicação aos times SAP, IRIS e GUS sobre o novo campo Atualização do layout de integração Testes integrados em ambiente controlado Liberação coordenada em produção 📈 Score (GUT) CritérioNotaGravity (Gravidade)5Urgency (Urgência)4Trend (Tendência)4GUT Total80 | S13: 2 | T13: =_xlfn.XLOOKUP(S13,Tabela4[Horas],Tabela4[Pontos],,1) -> 0.5 | U13: ENS-9957 | V13: ENS-10996 | W13: ENS-10997 | Y13: =HYPERLINK("https://tkebrasil.atlassian.net/browse/" & U13,U13) -> ENS-9957 | Z13: =HYPERLINK("https://tkebrasil.atlassian.net/browse/" & V13,V13) -> ENS-10996 | AA13: =HYPERLINK("https://tkebrasil.atlassian.net/browse/" & W13,W13) -> ENS-10997 | AC13: X | AD13: BL | AE13: =IF($AD13=AE$1,$U13) -> ENS-9957 | AF13: =IF($AD13=AF$1,$U13) -> FALSE | AG13: =IF($AD13=AG$1,$U13) -> FALSE | AH13: =IF($AD13=AH$1,$V13) -> ENS-10996 | AI13: =IF($AD13=AI$1,$V13) -> FALSE | AJ13: =IF($AD13=AJ$1,$V13) -> FALSE | AK13: =IF($AD13=AK$1,$W13) -> ENS-10997 | AL13: =IF($AD13=AL$1,$W13) -> FALSE | AM13: =IF($AD13=AM$1,$W13) -> FALSE | AN13: =IF(C13=0,"O","C") -> C | AO13: =IF(AND(AD13=Parâmetros!$J$3,AN13="C"),S13,0) -> 2 | AP13: =IF(AND(AD13=Parâmetros!$J$3,AN13="O"),S13,0) -> 0 | AQ13: =IF(AND(AD13=Parâmetros!$J$4,AN13="C"),S13,0) -> 0 | AR13: =IF(AND(AD13=Parâmetros!$J$4,AN13="O"),S13,0) -> 0 | AS13: =IF(AND(AD13=Parâmetros!$J$5,AN13="C"),S13,0) -> 0 | AT13: =IF(AND(AD13=Parâmetros!$J$5,AN13="O"),S13,0) -> 0
A14: =UPPER(LEFT(I14, 3)) -> ENS | B14: 2026-09-08 | C14: REQ0522963 | D14: SCTASK0727583 | F14: 0 | G14: INTERFACE | H14: NOVO DESENVOLVIMENTO | I14: ensemble@thyssenkruppelevadores.com.br | J14: Giovani Perotto Mesquita | K14: =_xlfn.XLOOKUP(Planilha!$J14,Tabela9[Pessoas],Tabela9[UUID Jira]) -> 712020:8364b9cf-88a2-4399-9f86-fff7bed77ce2 | L14: Luiz Felipe Brandão da Silva | M14: =_xlfn.XLOOKUP(Planilha!$L14,Tabela9[Pessoas],Tabela9[UUID Jira]) -> 6245e14af6a26900695d5c1c | N14: Criar alerta quando mensagem da Adobe chegar no webhook | O14: Criar alerta quando mensagem da Adobe chegar no webhook | P14: Criar alerta quando mensagem da Adobe chegar no webhook | Q14: Execução de Testes | R14: **OBJETIVO GERAL** [Descreva o objetivo geral da alteração] **ITENS A SEREM ATENDIDOS:** **1. [Item 1]** **1.1. Tipo de Funcionalidade:** [Informar o tipo de funcionalidade] **1.2. Complexidade:** [Alta, Média, Baixa, etc] **1.3. Protótipo de Tela:** [Informações a respeito do protótipo da tela] **1.4. Critérios de Validação:** a. [Critério de validação 1] b. [Critério de validação 2] | S14: 2 | T14: =_xlfn.XLOOKUP(S14,Tabela4[Horas],Tabela4[Pontos],,1) -> 0.5 | U14: ENS-10442 | V14: ENS-10998 | W14: ENS-10999 | Y14: =HYPERLINK("https://tkebrasil.atlassian.net/browse/" & U14,U14) -> ENS-10442 | Z14: =HYPERLINK("https://tkebrasil.atlassian.net/browse/" & V14,V14) -> ENS-10998 | AA14: =HYPERLINK("https://tkebrasil.atlassian.net/browse/" & W14,W14) -> ENS-10999 | AC14: X | AD14: BL | AE14: =IF($AD14=AE$1,$U14) -> ENS-10442 | AF14: =IF($AD14=AF$1,$U14) -> FALSE | AG14: =IF($AD14=AG$1,$U14) -> FALSE | AH14: =IF($AD14=AH$1,$V14) -> ENS-10998 | AI14: =IF($AD14=AI$1,$V14) -> FALSE | AJ14: =IF($AD14=AJ$1,$V14) -> FALSE | AK14: =IF($AD14=AK$1,$W14) -> ENS-10999 | AL14: =IF($AD14=AL$1,$W14) -> FALSE | AM14: =IF($AD14=AM$1,$W14) -> FALSE | AN14: =IF(C14=0,"O","C") -> C | AO14: =IF(AND(AD14=Parâmetros!$J$3,AN14="C"),S14,0) -> 2 | AP14: =IF(AND(AD14=Parâmetros!$J$3,AN14="O"),S14,0) -> 0 | AQ14: =IF(AND(AD14=Parâmetros!$J$4,AN14="C"),S14,0) -> 0 | AR14: =IF(AND(AD14=Parâmetros!$J$4,AN14="O"),S14,0) -> 0 | AS14: =IF(AND(AD14=Parâmetros!$J$5,AN14="C"),S14,0) -> 0 | AT14: =IF(AND(AD14=Parâmetros!$J$5,AN14="O"),S14,0) -> 0
A15: =UPPER(LEFT(I15, 3)) -> ENS | B15: 2026-09-08 | C15: REQ0522901 | D15: SCTASK0727520 | F15: 0 | G15: INTERFACE | H15: NOVO DESENVOLVIMENTO | I15: ensemble@thyssenkruppelevadores.com.br | J15: Giovani Perotto Mesquita | K15: =_xlfn.XLOOKUP(Planilha!$J15,Tabela9[Pessoas],Tabela9[UUID Jira]) -> 712020:8364b9cf-88a2-4399-9f86-fff7bed77ce2 | L15: Regina Albanus | M15: =_xlfn.XLOOKUP(Planilha!$L15,Tabela9[Pessoas],Tabela9[UUID Jira]) -> 557058:330c824e-66ab-4df0-b7eb-8ddf9d578a4e | N15: Implementar API Soluti timestamp | O15: Implementar API Soluti timestamp | P15: Implementar API Soluti timestamp | Q15: Execução de Testes | R15: **OBJETIVO GERAL** [Descreva o objetivo geral da alteração] **ITENS A SEREM ATENDIDOS:** **1. [Item 1]** **1.1. Tipo de Funcionalidade:** [Informar o tipo de funcionalidade] **1.2. Complexidade:** [Alta, Média, Baixa, etc] **1.3. Protótipo de Tela:** [Informações a respeito do protótipo da tela] **1.4. Critérios de Validação:** a. [Critério de validação 1] b. [Critério de validação 2] | S15: 4 | T15: =_xlfn.XLOOKUP(S15,Tabela4[Horas],Tabela4[Pontos],,1) -> 0.5 | U15: ENS-10362 | V15: ENS-11000 | W15: ENS-11001 | Y15: =HYPERLINK("https://tkebrasil.atlassian.net/browse/" & U15,U15) -> ENS-10362 | Z15: =HYPERLINK("https://tkebrasil.atlassian.net/browse/" & V15,V15) -> ENS-11000 | AA15: =HYPERLINK("https://tkebrasil.atlassian.net/browse/" & W15,W15) -> ENS-11001 | AC15: X | AD15: BL | AE15: =IF($AD15=AE$1,$U15) -> ENS-10362 | AF15: =IF($AD15=AF$1,$U15) -> FALSE | AG15: =IF($AD15=AG$1,$U15) -> FALSE | AH15: =IF($AD15=AH$1,$V15) -> ENS-11000 | AI15: =IF($AD15=AI$1,$V15) -> FALSE | AJ15: =IF($AD15=AJ$1,$V15) -> FALSE | AK15: =IF($AD15=AK$1,$W15) -> ENS-11001 | AL15: =IF($AD15=AL$1,$W15) -> FALSE | AM15: =IF($AD15=AM$1,$W15) -> FALSE | AN15: =IF(C15=0,"O","C") -> C | AO15: =IF(AND(AD15=Parâmetros!$J$3,AN15="C"),S15,0) -> 4 | AP15: =IF(AND(AD15=Parâmetros!$J$3,AN15="O"),S15,0) -> 0 | AQ15: =IF(AND(AD15=Parâmetros!$J$4,AN15="C"),S15,0) -> 0 | AR15: =IF(AND(AD15=Parâmetros!$J$4,AN15="O"),S15,0) -> 0 | AS15: =IF(AND(AD15=Parâmetros!$J$5,AN15="C"),S15,0) -> 0 | AT15: =IF(AND(AD15=Parâmetros!$J$5,AN15="O"),S15,0) -> 0
A16: =UPPER(LEFT(I16, 3)) -> ENS | B16: 2026-09-08 | C16: REQ0482512 | D16: SCTASK0708892 | F16: 0 | G16: INTERFACE | H16: NOVO DESENVOLVIMENTO | I16: ensemble@thyssenkruppelevadores.com.br | J16: Giovani Perotto Mesquita | K16: =_xlfn.XLOOKUP(Planilha!$J16,Tabela9[Pessoas],Tabela9[UUID Jira]) -> 712020:8364b9cf-88a2-4399-9f86-fff7bed77ce2 | L16: Pablo Rocha | M16: =_xlfn.XLOOKUP(Planilha!$L16,Tabela9[Pessoas],Tabela9[UUID Jira]) -> 557058:004709f9-0a88-4979-a875-f58ca3985cf7 | N16: Enviar CPF via jspv | O16: Enviar CPF via jspv | P16: Enviar CPF via jspv | Q16: Execução de Testes | R16: Demanda da Stephanie, segunda a mesma seria só incluir este campo | S16: 2 | T16: =_xlfn.XLOOKUP(S16,Tabela4[Horas],Tabela4[Pontos],,1) -> 0.5 | U16: ENS-10576 | V16: ENS-11002 | W16: ENS-11003 | Y16: =HYPERLINK("https://tkebrasil.atlassian.net/browse/" & U16,U16) -> ENS-10576 | Z16: =HYPERLINK("https://tkebrasil.atlassian.net/browse/" & V16,V16) -> ENS-11002 | AA16: =HYPERLINK("https://tkebrasil.atlassian.net/browse/" & W16,W16) -> ENS-11003 | AC16: X | AD16: BL | AE16: =IF($AD16=AE$1,$U16) -> ENS-10576 | AF16: =IF($AD16=AF$1,$U16) -> FALSE | AG16: =IF($AD16=AG$1,$U16) -> FALSE | AH16: =IF($AD16=AH$1,$V16) -> ENS-11002 | AI16: =IF($AD16=AI$1,$V16) -> FALSE | AJ16: =IF($AD16=AJ$1,$V16) -> FALSE | AK16: =IF($AD16=AK$1,$W16) -> ENS-11003 | AL16: =IF($AD16=AL$1,$W16) -> FALSE | AM16: =IF($AD16=AM$1,$W16) -> FALSE | AN16: =IF(C16=0,"O","C") -> C | AO16: =IF(AND(AD16=Parâmetros!$J$3,AN16="C"),S16,0) -> 2 | AP16: =IF(AND(AD16=Parâmetros!$J$3,AN16="O"),S16,0) -> 0 | AQ16: =IF(AND(AD16=Parâmetros!$J$4,AN16="C"),S16,0) -> 0 | AR16: =IF(AND(AD16=Parâmetros!$J$4,AN16="O"),S16,0) -> 0 | AS16: =IF(AND(AD16=Parâmetros!$J$5,AN16="C"),S16,0) -> 0 | AT16: =IF(AND(AD16=Parâmetros!$J$5,AN16="O"),S16,0) -> 0
A17: =UPPER(LEFT(I17, 3)) -> ENS | B17: 2026-09-08 | C17: REQ0526341 | D17: SCTASK0744373 | F17: 0 | G17: INTERFACE | H17: NOVO DESENVOLVIMENTO | I17: ensemble@thyssenkruppelevadores.com.br | J17: Giovani Perotto Mesquita | K17: =_xlfn.XLOOKUP(Planilha!$J17,Tabela9[Pessoas],Tabela9[UUID Jira]) -> 712020:8364b9cf-88a2-4399-9f86-fff7bed77ce2 | L17: Luiz Felipe Brandão da Silva | M17: =_xlfn.XLOOKUP(Planilha!$L17,Tabela9[Pessoas],Tabela9[UUID Jira]) -> 6245e14af6a26900695d5c1c | N17: Criar um fluxo de dados para capturar as informações de DOT.CALCULO provenientes do Dossiê Técnico | O17: Criar um fluxo de dados para capturar as informações de DOT.CALCULO provenientes do Dossiê Técnico | P17: Criar um fluxo de dados para capturar as informações de DOT.CALCULO provenientes do Dossiê Técnico | Q17: Execução de Testes | R17: 🧾 Definição da Necessidade Criar um fluxo de dados para capturar as informações de DOT.CALCULO provenientes do Dossiê Técnico, persistindo os dados transitados no IRIS por meio de uma tabela federada, viabilizando a disponibilidade e rastreabilidade das informações para consumo futuro. Fonte: SCTASK0744373 🧑‍💼 Contato PO: Robson Portella 📖 Título da User Story Como responsável pelo consumo de informações do Dossiê Técnico, quero que os dados de DOT.CALCULO sejam persistidos em uma tabela federada no IRIS, para que as informações transitadas possam ser armazenadas e disponibilizadas de forma estruturada para utilização posterior. 📊 Priorização Prioridade: Alta Justificativa: Valor de negócio: Permite a disponibilização estruturada dos dados do Dossiê Técnico. Impacto: Cria a base necessária para consultas e integrações futuras. Urgência: Existe uma solicitação explícita para implementação do fluxo de persistência. Dependências: A persistência em tabela federada é pré-requisito para qualquer consumo analítico ou operacional destes dados. 🔍 Processo Atual (AS IS) Os dados de DOT.CALCULO transitam pelo processo do Dossiê Técnico, porém não existe uma persistência das informações em uma tabela federada dentro do IRIS. 🚀 Processo Futuro (TO BE) Os dados de DOT.CALCULO serão capturados durante sua transitação no processo do Dossiê Técnico e persistidos automaticamente em uma tabela federada no IRIS, permitindo sua consulta e utilização por consumidores autorizados. 🎯 Objetivo da Mudança Implementar um mecanismo de persistência dos dados DOT.CALCULO em uma tabela federada no IRIS, garantindo armazenamento estruturado das informações transitadas e disponibilidade para usos futuros. ❌ Fora de Escopo Criação de dashboards ou relatórios. Desenvolvimento de consultas analíticas. Alterações na origem dos dados do Dossiê Técnico. Mudanças em sistemas consumidores. Processamento ou transformação de dados não relacionados ao objeto DOT.CALCULO. ✅ Critérios de Aceite (BDD) Cenário 1: Persistir dados recebidos Dado que existam informações de DOT.CALCULO transitando pelo processo do Dossiê Técnico Quando o fluxo de captura for executado Então os dados deverão ser persistidos em uma tabela federada no IRIS. Cenário 2: Disponibilizar dados persistidos Dado que registros tenham sido persistidos na tabela federada Quando a tabela for consultada Então os registros armazenados deverão estar disponíveis para consulta. Cenário 3: Integridade da persistência Dado que informações de DOT.CALCULO sejam processadas Quando a gravação ocorrer na tabela federada Então os dados persistidos deverão corresponder aos dados recebidos pelo fluxo. 🧪 Cenários de Teste de Validação Cenário 1: Persistência de registro válido Pré-condições Fluxo implantado. Existência de dados de DOT.CALCULO para processamento. Passos Enviar um registro contendo informações de DOT.CALCULO. Aguardar o processamento do fluxo. Consultar a tabela federada. Resultado Esperado O registro é encontrado na tabela federada do IRIS. Cenário 2: Persistência de múltiplos registros Pré-condições Fluxo operacional. Passos Processar múltiplos registros DOT.CALCULO. Consultar a tabela federada. Resultado Esperado Todos os registros processados encontram-se armazenados. Cenário 3: Disponibilidade para consulta Pré-condições Existência de registros persistidos. Passos Realizar consulta na tabela federada. Verificar retorno dos registros. Resultado Esperado Os dados persistidos são retornados corretamente. ❌ Cenários de Teste de Rejeição Cenário 1: Falha na persistência Pré-condições Fluxo executando. Passos Processar um registro DOT.CALCULO. Consultar a tabela federada. Resultado Esperado O teste falha caso o registro não seja encontrado na tabela. Cenário 2: Divergência de informações Pré-condições Registro processado. Passos Comparar os dados recebidos com os dados gravados. Validar integridade das informações. Resultado Esperado O teste falha caso existam divergências entre origem e persistência. 🔄 Cenários de Teste de Regressão Cenário 1: Continuidade do fluxo atual Pré-condições Processo existente em funcionamento. Passos Executar o processamento normal do Dossiê Técnico. Monitorar comportamento da integração. Resultado Esperado O fluxo original permanece operacional sem impactos. Cenário 2: Persistência sem interferência Pré-condições Fluxo implantado. Passos Processar registros normalmente. Validar a persistência. Validar a continuidade do processamento. Resultado Esperado A gravação na tabela federada não afeta o fluxo de origem. 🧭 Sugestão de Cutover Comunicação Informar equipes consumidoras sobre a disponibilização da nova estrutura de persistência. Implantação Publicar o fluxo de captura e persistência em ambiente produtivo. Testes em Produção Executar processamento controlado de registros DOT.CALCULO. Validar a gravação na tabela federada. Monitoramento Inicial Acompanhar o volume de registros persistidos. Verificar possíveis falhas de gravação após a entrada em produção. 📈 Score (GUT) Critério NotaGravidade 4 Urgência 4 Tendência 4 GUT = 64 Justificativa A persistência dos dados é necessária para garantir disponibilidade e rastreabilidade das informações do Dossiê Técnico. A ausência dessa estrutura pode limitar futuras consultas e integrações, justificando uma classificação elevada, embora não crítica. | S17: 4 | T17: =_xlfn.XLOOKUP(S17,Tabela4[Horas],Tabela4[Pontos],,1) -> 0.5 | U17: ENS-10673 | V17: ENS-11004 | W17: ENS-11005 | Y17: =HYPERLINK("https://tkebrasil.atlassian.net/browse/" & U17,U17) -> ENS-10673 | Z17: =HYPERLINK("https://tkebrasil.atlassian.net/browse/" & V17,V17) -> ENS-11004 | AA17: =HYPERLINK("https://tkebrasil.atlassian.net/browse/" & W17,W17) -> ENS-11005 | AC17: X | AD17: BL | AE17: =IF($AD17=AE$1,$U17) -> ENS-10673 | AF17: =IF($AD17=AF$1,$U17) -> FALSE | AG17: =IF($AD17=AG$1,$U17) -> FALSE | AH17: =IF($AD17=AH$1,$V17) -> ENS-11004 | AI17: =IF($AD17=AI$1,$V17) -> FALSE | AJ17: =IF($AD17=AJ$1,$V17) -> FALSE | AK17: =IF($AD17=AK$1,$W17) -> ENS-11005 | AL17: =IF($AD17=AL$1,$W17) -> FALSE | AM17: =IF($AD17=AM$1,$W17) -> FALSE | AN17: =IF(C17=0,"O","C") -> C | AO17: =IF(AND(AD17=Parâmetros!$J$3,AN17="C"),S17,0) -> 4 | AP17: =IF(AND(AD17=Parâmetros!$J$3,AN17="O"),S17,0) -> 0 | AQ17: =IF(AND(AD17=Parâmetros!$J$4,AN17="C"),S17,0) -> 0 | AR17: =IF(AND(AD17=Parâmetros!$J$4,AN17="O"),S17,0) -> 0 | AS17: =IF(AND(AD17=Parâmetros!$J$5,AN17="C"),S17,0) -> 0 | AT17: =IF(AND(AD17=Parâmetros!$J$5,AN17="O"),S17,0) -> 0
A18: =UPPER(LEFT(I18, 3)) -> ENS | B18: 2026-09-08 | C18: 0 | D18: 0 | F18: 0 | G18: INTERFACE | H18: NOVO DESENVOLVIMENTO | I18: ensemble@thyssenkruppelevadores.com.br | J18: Giovani Perotto Mesquita | K18: =_xlfn.XLOOKUP(Planilha!$J18,Tabela9[Pessoas],Tabela9[UUID Jira]) -> 712020:8364b9cf-88a2-4399-9f86-fff7bed77ce2 | L18: Regina Albanus | M18: =_xlfn.XLOOKUP(Planilha!$L18,Tabela9[Pessoas],Tabela9[UUID Jira]) -> 557058:330c824e-66ab-4df0-b7eb-8ddf9d578a4e | N18: Criar dashboard de negócios do IRIS | O18: Criar dashboard de negócios do IRIS | P18: Criar dashboard de negócios do IRIS | Q18: Implementação | R18: Ver DoR | S18: 2 | T18: =_xlfn.XLOOKUP(S18,Tabela4[Horas],Tabela4[Pontos],,1) -> 0.5 | U18: ENS-10676 | V18: ENS-11006 | W18: ENS-11007 | Y18: =HYPERLINK("https://tkebrasil.atlassian.net/browse/" & U18,U18) -> ENS-10676 | Z18: =HYPERLINK("https://tkebrasil.atlassian.net/browse/" & V18,V18) -> ENS-11006 | AA18: =HYPERLINK("https://tkebrasil.atlassian.net/browse/" & W18,W18) -> ENS-11007 | AC18: X | AD18: BL | AE18: =IF($AD18=AE$1,$U18) -> ENS-10676 | AF18: =IF($AD18=AF$1,$U18) -> FALSE | AG18: =IF($AD18=AG$1,$U18) -> FALSE | AH18: =IF($AD18=AH$1,$V18) -> ENS-11006 | AI18: =IF($AD18=AI$1,$V18) -> FALSE | AJ18: =IF($AD18=AJ$1,$V18) -> FALSE | AK18: =IF($AD18=AK$1,$W18) -> ENS-11007 | AL18: =IF($AD18=AL$1,$W18) -> FALSE | AM18: =IF($AD18=AM$1,$W18) -> FALSE | AN18: =IF(C18=0,"O","C") -> O | AO18: =IF(AND(AD18=Parâmetros!$J$3,AN18="C"),S18,0) -> 0 | AP18: =IF(AND(AD18=Parâmetros!$J$3,AN18="O"),S18,0) -> 2 | AQ18: =IF(AND(AD18=Parâmetros!$J$4,AN18="C"),S18,0) -> 0 | AR18: =IF(AND(AD18=Parâmetros!$J$4,AN18="O"),S18,0) -> 0 | AS18: =IF(AND(AD18=Parâmetros!$J$5,AN18="C"),S18,0) -> 0 | AT18: =IF(AND(AD18=Parâmetros!$J$5,AN18="O"),S18,0) -> 0
A19: =UPPER(LEFT(I19, 3)) -> ENS | B19: 2026-09-08 | C19: REQ0525598 | D19: SCTASK0730907 | F19: 0 | G19: INTERFACE | H19: NOVO DESENVOLVIMENTO | I19: ensemble@thyssenkruppelevadores.com.br | J19: Giovani Perotto Mesquita | K19: =_xlfn.XLOOKUP(Planilha!$J19,Tabela9[Pessoas],Tabela9[UUID Jira]) -> 712020:8364b9cf-88a2-4399-9f86-fff7bed77ce2 | L19: Pablo Rocha | M19: =_xlfn.XLOOKUP(Planilha!$L19,Tabela9[Pessoas],Tabela9[UUID Jira]) -> 557058:004709f9-0a88-4979-a875-f58ca3985cf7 | N19: Criar e parametrizar IOT Dynamox | O19: Criar e parametrizar IOT Dynamox | P19: Criar e parametrizar IOT Dynamox | Q19: Execução de Testes | R19: Criar e parametrizar IOT Dynamox | S19: 4 | T19: =_xlfn.XLOOKUP(S19,Tabela4[Horas],Tabela4[Pontos],,1) -> 0.5 | U19: ENS-10380 | V19: ENS-11008 | W19: ENS-11009 | Y19: =HYPERLINK("https://tkebrasil.atlassian.net/browse/" & U19,U19) -> ENS-10380 | Z19: =HYPERLINK("https://tkebrasil.atlassian.net/browse/" & V19,V19) -> ENS-11008 | AA19: =HYPERLINK("https://tkebrasil.atlassian.net/browse/" & W19,W19) -> ENS-11009 | AC19: X | AD19: BL | AE19: =IF($AD19=AE$1,$U19) -> ENS-10380 | AF19: =IF($AD19=AF$1,$U19) -> FALSE | AG19: =IF($AD19=AG$1,$U19) -> FALSE | AH19: =IF($AD19=AH$1,$V19) -> ENS-11008 | AI19: =IF($AD19=AI$1,$V19) -> FALSE | AJ19: =IF($AD19=AJ$1,$V19) -> FALSE | AK19: =IF($AD19=AK$1,$W19) -> ENS-11009 | AL19: =IF($AD19=AL$1,$W19) -> FALSE | AM19: =IF($AD19=AM$1,$W19) -> FALSE | AN19: =IF(C19=0,"O","C") -> C | AO19: =IF(AND(AD19=Parâmetros!$J$3,AN19="C"),S19,0) -> 4 | AP19: =IF(AND(AD19=Parâmetros!$J$3,AN19="O"),S19,0) -> 0 | AQ19: =IF(AND(AD19=Parâmetros!$J$4,AN19="C"),S19,0) -> 0 | AR19: =IF(AND(AD19=Parâmetros!$J$4,AN19="O"),S19,0) -> 0 | AS19: =IF(AND(AD19=Parâmetros!$J$5,AN19="C"),S19,0) -> 0 | AT19: =IF(AND(AD19=Parâmetros!$J$5,AN19="O"),S19,0) -> 0
