Workbook

Sheet Planilha
A1: Projeto | B1: Data | C1: Request | D1: Task | E1: Prioridade | F1: Retorno | G1: Módulo | H1: Tipo | I1: Usuário Projeto | J1: PO | K1: UUID PO | L1: Recurso | M1: UUID Recurso | N1: Épico | O1: Estória | P1: Tarefa | Q1: Etapa | R1: US | S1: Horas | T1: Pontos | U1: TicketE | V1: TicketS | W1: TicketT | X1: Jira | AC1: Alocadas | AD1: Tipo | AE1: =Parâmetros!$J3 | AF1: =Parâmetros!$J4 | AG1: =Parâmetros!$J5 | AH1: =Parâmetros!$J3 | AI1: =Parâmetros!$J4 | AJ1: =Parâmetros!$J5 | AK1: =Parâmetros!$J3 | AL1: =Parâmetros!$J4 | AM1: =Parâmetros!$J5
A2: =UPPER(LEFT(I2, 3)) | B2: 2026-08-10 | C2: 0 | D2: 0 | F2: 0 | G2: INTERFACE | H2: ALTERAÇÃO | I2: ensemble@thyssenkruppelevadores.com.br | J2: Giovani Perotto Mesquita | K2: =_xlfn.XLOOKUP(Planilha!$J2,Tabela9[Pessoas],Tabela9[UUID Jira]) | L2: Alexandre Trindade Pereira | M2: =_xlfn.XLOOKUP(Planilha!$L2,Tabela9[Pessoas],Tabela9[UUID Jira]) | N2: Confeccionar logs para auditoria | O2: Confeccionar logs para auditoria | P2: Confeccionar logs para auditoria | Q2: Implementação | R2: Confeccionar logs para auditoria | S2: 10 | T2: =_xlfn.XLOOKUP(S2,Tabela4[Horas],Tabela4[Pontos],,1) | U2: ENS-10640 | V2: ENS-10723 | W2: ENS-10724 | Y2: =HYPERLINK("https://tkebrasil.atlassian.net/browse/" & U2,U2) | Z2: =HYPERLINK("https://tkebrasil.atlassian.net/browse/" & V2,V2) | AA2: =HYPERLINK("https://tkebrasil.atlassian.net/browse/" & W2,W2) | AC2: X | AD2: CR | AE2: =IF($AD2=AE$1,$U2) | AF2: =IF($AD2=AF$1,$U2) | AG2: =IF($AD2=AG$1,$U2) | AH2: =IF($AD2=AH$1,$V2) | AI2: =IF($AD2=AI$1,$V2) | AJ2: =IF($AD2=AJ$1,$V2) | AK2: =IF($AD2=AK$1,$W2) | AL2: =IF($AD2=AL$1,$W2) | AM2: =IF($AD2=AM$1,$W2)
A3: =UPPER(LEFT(I3, 3)) | B3: 2026-08-10 | C3: REQ0339905 | D3: SCTASK0581534 | F3: 0 | G3: INTERFACE | H3: NOVO DESENVOLVIMENTO | I3: ensemble@thyssenkruppelevadores.com.br | J3: Giovani Perotto Mesquita | K3: =_xlfn.XLOOKUP(Planilha!$J3,Tabela9[Pessoas],Tabela9[UUID Jira]) | L3: Tanise Sarmento | M3: =_xlfn.XLOOKUP(Planilha!$L3,Tabela9[Pessoas],Tabela9[UUID Jira]) | N3: PO - Menus Intec | O3: PO - Menus Intec | P3: PO - Menus Intec | Q3: Implementação | R3: PO - Menus Intec | S3: 1 | T3: =_xlfn.XLOOKUP(S3,Tabela4[Horas],Tabela4[Pontos],,1) | U3: ENS-10725 | V3: ENS-10726 | W3: ENS-10727 | Y3: =HYPERLINK("https://tkebrasil.atlassian.net/browse/" & U3,U3) | Z3: =HYPERLINK("https://tkebrasil.atlassian.net/browse/" & V3,V3) | AA3: =HYPERLINK("https://tkebrasil.atlassian.net/browse/" & W3,W3) | AC3: X | AD3: MP | AE3: =IF($AD3=AE$1,$U3) | AF3: =IF($AD3=AF$1,$U3) | AG3: =IF($AD3=AG$1,$U3) | AH3: =IF($AD3=AH$1,$V3) | AI3: =IF($AD3=AI$1,$V3) | AJ3: =IF($AD3=AJ$1,$V3) | AK3: =IF($AD3=AK$1,$W3) | AL3: =IF($AD3=AL$1,$W3) | AM3: =IF($AD3=AM$1,$W3)
A4: =UPPER(LEFT(I4, 3)) | B4: 2026-08-10 | C4: 0 | D4: 0 | F4: 0 | G4: INTERFACE | H4: ALTERAÇÃO | I4: ensemble@thyssenkruppelevadores.com.br | J4: Giovani Perotto Mesquita | K4: =_xlfn.XLOOKUP(Planilha!$J4,Tabela9[Pessoas],Tabela9[UUID Jira]) | L4: Luis Henrique Petkovicz | M4: =_xlfn.XLOOKUP(Planilha!$L4,Tabela9[Pessoas],Tabela9[UUID Jira]) | N4: Atividades Administrativas | O4: Atividades Administrativas | P4: Atividades Administrativas | Q4: Implementação | R4: Atividades Administrativas | S4: 10 | T4: =_xlfn.XLOOKUP(S4,Tabela4[Horas],Tabela4[Pontos],,1) | U4: ENS-8159 | V4: ENS-10728 | W4: ENS-10729 | Y4: =HYPERLINK("https://tkebrasil.atlassian.net/browse/" & U4,U4) | Z4: =HYPERLINK("https://tkebrasil.atlassian.net/browse/" & V4,V4) | AA4: =HYPERLINK("https://tkebrasil.atlassian.net/browse/" & W4,W4) | AC4: X | AD4: BL | AE4: =IF($AD4=AE$1,$U4) | AF4: =IF($AD4=AF$1,$U4) | AG4: =IF($AD4=AG$1,$U4) | AH4: =IF($AD4=AH$1,$V4) | AI4: =IF($AD4=AI$1,$V4) | AJ4: =IF($AD4=AJ$1,$V4) | AK4: =IF($AD4=AK$1,$W4) | AL4: =IF($AD4=AL$1,$W4) | AM4: =IF($AD4=AM$1,$W4)
A5: =UPPER(LEFT(I5, 3)) | B5: 2026-08-10 | C5: 0 | D5: 0 | F5: 0 | G5: INTERFACE | H5: ALTERAÇÃO | I5: ensemble@thyssenkruppelevadores.com.br | J5: Giovani Perotto Mesquita | K5: =_xlfn.XLOOKUP(Planilha!$J5,Tabela9[Pessoas],Tabela9[UUID Jira]) | L5: Luis Henrique Petkovicz | M5: =_xlfn.XLOOKUP(Planilha!$L5,Tabela9[Pessoas],Tabela9[UUID Jira]) | N5: Automatizar script de limpeza de Logs XV | O5: Automatizar script de limpeza de Logs XV | P5: Automatizar script de limpeza de Logs XV | Q5: Implementação | R5: **OBJETIVO GERAL** [Descreva o objetivo geral da alteração] **ITENS A SEREM ATENDIDOS:** **1. [Item 1]** **1.1. Tipo de Funcionalidade:** [Informar o tipo de funcionalidade] **1.2. Complexidade:** [Alta, Média, Baixa, etc] **1.3. Protótipo de Tela:** [Informações a respeito do protótipo da tela] **1.4. Critérios de Validação:** a. [Critério de validação 1] b. [Critério de validação 2] | S5: 4 | T5: =_xlfn.XLOOKUP(S5,Tabela4[Horas],Tabela4[Pontos],,1) | U5: ENS-9017 | V5: ENS-10730 | W5: ENS-10731 | Y5: =HYPERLINK("https://tkebrasil.atlassian.net/browse/" & U5,U5) | Z5: =HYPERLINK("https://tkebrasil.atlassian.net/browse/" & V5,V5) | AA5: =HYPERLINK("https://tkebrasil.atlassian.net/browse/" & W5,W5) | AC5: X | AD5: BL | AE5: =IF($AD5=AE$1,$U5) | AF5: =IF($AD5=AF$1,$U5) | AG5: =IF($AD5=AG$1,$U5) | AH5: =IF($AD5=AH$1,$V5) | AI5: =IF($AD5=AI$1,$V5) | AJ5: =IF($AD5=AJ$1,$V5) | AK5: =IF($AD5=AK$1,$W5) | AL5: =IF($AD5=AL$1,$W5) | AM5: =IF($AD5=AM$1,$W5)
A6: =UPPER(LEFT(I6, 3)) | B6: 2026-08-10 | C6: REQ0377661 | D6: SCTASK0579990 | F6: 0 | G6: INTERFACE | H6: NOVO DESENVOLVIMENTO | I6: ensemble@thyssenkruppelevadores.com.br | J6: Giovani Perotto Mesquita | K6: =_xlfn.XLOOKUP(Planilha!$J6,Tabela9[Pessoas],Tabela9[UUID Jira]) | L6: Pablo Rocha | M6: =_xlfn.XLOOKUP(Planilha!$L6,Tabela9[Pessoas],Tabela9[UUID Jira]) | N6: Integração de Margens entre GUS e E‑Sales | O6: Integração de Margens entre GUS e E‑Sales | P6: Integração de Margens entre GUS e E‑Sales | Q6: Implementação | R6: 🌐 ÉPICO – Integração de Margens entre GUS e E‑Sales 🏷 Título do Épico Integração das Margens com e sem Desconto entre GUS e E‑Sales para Suporte ao Processo Comercial 🧾 Descrição Geral Este épico tem como objetivo estabelecer uma nova integração padronizada, confiável e automatizada entre os sistemas GUS e E‑Sales, permitindo o trânsito de informações de margem com desconto e margem sem desconto. A iniciativa busca eliminar atividades manuais, reduzir inconsistências, aumentar a velocidade das operações comerciais e aprimorar a tomada de decisão baseada em dados. PO Bruno Fuentes (Zallpy) Tiago Fogaça (PO) Victor Augusto Santos Marinho (Zallpy) 🎯 Objetivo Estratégico Garantir que o processo comercial opere com informações atualizadas, consistentes e rastreáveis. Apoiar decisões de precificação e propostas comerciais com dados íntegros. Reduzir riscos operacionais e retrabalho decorrentes de processos manuais. Aumentar eficiência e performance dos times comercial e financeiro. 📌 Escopo do Épico Inclui: Construção de interfaces de envio das margens com e sem desconto do GUS para o E‑Sales. Padronização de layouts, validações e regras de negócio. Implementação de logs, rastreabilidade, controle de erros e tratamento de rejeições. Testes funcionais, integrados, regressivos e de migração. Não inclui: Alterações no cálculo das margens. Modificações em regras de negócio internas do GUS ou do E‑Sales. Criação de dashboards ou relatórios derivados. 🗂 User Stories Associadas US – Enviar Margem com Desconto do GUS para o E‑Sales US – Enviar Margem sem Desconto do GUS para o E‑Sales (As histórias permanecem independentes para entrega incremental, mas agrupadas sob o mesmo objetivo macro.) 🧑‍💼 Stakeholders Envolvidos Área Comercial Área Financeira Equipe de Produto (IRIS ESB) Time responsável pelo GUS Time responsável pelo E‑Sales Time de Arquitetura e Governança de Integrações QA / Homologação 🚀 Benefícios Esperados Redução de erros manuais no processo de pricing. Aumento da confiabilidade das informações de margem. Otimização das operações comerciais (tempo de cotação). Aumento da precisão nas projeções financeiras e análises de margem. Melhor experiência para os usuários das áreas comercial e financeira. 🔄 Critérios de Aceitação do Épico O épico será considerado concluído quando: Ambas as interfaces (com e sem desconto) estiverem implementadas, testadas e homologadas. Processos de envio, rejeição, reprocessamento e logs estiverem implementados. Todos os ambientes (DEV, TQA e PRD) estiverem configurados e validados. Toda documentação funcional e técnica tiver sido atualizada. O time comercial confirmar que os dados estão disponíveis e íntegros no E‑Sales. 🧭 Cutover do Épico Comunicação às áreas usuárias sobre os novos fluxos. Treinamento rápido sobre leitura e impacto das margens no E‑Sales. Execução de testes fim a fim antes do go‑live. Reprocessamento inicial das margens para garantir baseline consistente. Monitoramento reforçado nas primeiras 72 horas pós-implantação. 📈 GUT Score do Épico Gravidade: 8 Urgência: 7 Tendência: 8 Total: 448 (Alta Prioridade Estratégica) | S6: 2 | T6: =_xlfn.XLOOKUP(S6,Tabela4[Horas],Tabela4[Pontos],,1) | U6: ENS-8908 | V6: ENS-10732 | W6: ENS-10733 | Y6: =HYPERLINK("https://tkebrasil.atlassian.net/browse/" & U6,U6) | Z6: =HYPERLINK("https://tkebrasil.atlassian.net/browse/" & V6,V6) | AA6: =HYPERLINK("https://tkebrasil.atlassian.net/browse/" & W6,W6) | AC6: X | AD6: BL | AE6: =IF($AD6=AE$1,$U6) | AF6: =IF($AD6=AF$1,$U6) | AG6: =IF($AD6=AG$1,$U6) | AH6: =IF($AD6=AH$1,$V6) | AI6: =IF($AD6=AI$1,$V6) | AJ6: =IF($AD6=AJ$1,$V6) | AK6: =IF($AD6=AK$1,$W6) | AL6: =IF($AD6=AL$1,$W6) | AM6: =IF($AD6=AM$1,$W6)
A7: =UPPER(LEFT(I7, 3)) | B7: 2026-08-10 | C7: 0 | D7: 0 | F7: 0 | G7: INTERFACE | H7: NOVO DESENVOLVIMENTO | I7: ensemble@thyssenkruppelevadores.com.br | J7: Giovani Perotto Mesquita | K7: =_xlfn.XLOOKUP(Planilha!$J7,Tabela9[Pessoas],Tabela9[UUID Jira]) | L7: Luis Henrique Petkovicz | M7: =_xlfn.XLOOKUP(Planilha!$L7,Tabela9[Pessoas],Tabela9[UUID Jira]) | N7: Alterar logs do IRIS para tabela federada | O7: Alterar logs do IRIS para tabela federada 1 | P7: Alterar logs do IRIS para tabela federada 1 | Q7: Implementação | R7: ✅ User Story 1 — Persistência Estruturada de Logs de Auditoria 🧾 Requisito Definido Implementar mecanismo de persistência estruturada para logs de auditoria do middleware, garantindo rastreabilidade, governança operacional e suporte aos processos de ITSM (ITIL). Os registros deverão contemplar, no mínimo, os seguintes atributos: Status: classificação do registro conforme análise do AMS (Application Management Services), indicando o estado operacional, tratamento ou encaminhamento do evento; UC – Caso de Uso: identificação do uso de caso ou fluxo de negócio associado ao registro, viabilizando rastreabilidade ponta a ponta para fins de auditoria e investigação; Criticidade: nível de impacto do evento (baixa, média ou alta), suportando priorização operacional e gestão de incidentes; Incidente/Requisição: referência ao incidente ou requisição registrada no sistema de ITSM, quando houver necessidade de abertura de ticket, assegurando integração com os processos de Incident e Request Management. Essa persistência deverá permitir auditorias técnicas e funcionais, apoiar análises de causa raiz, além de atender requisitos de compliance, observabilidade e melhoria contínua do ambiente de integração. 🧑‍💼 Contato Giovani Mesquita – Product Owner AMS (Application Management Services) Equipe de Middleware / Integração Governança de TI / ITSM 📖 Título da User Story Como Product Owner, quero que o middleware persista logs de auditoria de forma estruturada, para que seja possível garantir rastreabilidade, governança operacional e suporte aos processos de ITSM. 📊 Priorização Alta Justificativa: Alto valor para compliance, auditoria e governança Impacto direto na operação e no suporte (Incident/Request Management) Necessário para análise de causa raiz e melhoria contínua Dependência para processos operacionais e auditorias futuras 🔍 Processo Atual (AS IS) Atualmente, o middleware não possui um mecanismo estruturado e persistente para registro de logs de auditoria, dificultando a rastreabilidade de eventos, investigações operacionais, auditorias técnicas e integração com processos de ITSM. 🚀 Processo Futuro (TO BE) O middleware passará a registrar e persistir logs de auditoria de forma estruturada, contendo informações essenciais para análise operacional, auditoria e governança, permitindo integração com processos de Incident e Request Management. 🎯 Objetivo da Mudança Garantir rastreabilidade ponta a ponta dos eventos do middleware Apoiar auditorias técnicas e funcionais Facilitar análises de causa raiz Suportar compliance, observabilidade e melhoria contínua Integrar os eventos do middleware aos processos de ITSM ❌ Fora de Escopo Criação ou customização do sistema de ITSM Dashboards analíticos ou relatórios avançados Automação de abertura de tickets Retenção histórica além do definido pelo middleware ✅ Critérios de Aceitação (BDD) Cenário 1 – Persistência correta dos logs Dado que um evento ocorre no middleware Quando o log de auditoria é registrado Então o registro deve ser persistido contendo Status, Caso de Uso, Criticidade e referência a Incidente/Requisição (quando aplicável) Cenário 2 – Registro de criticidade Dado um evento com impacto operacional Quando o log é persistido Então a criticidade deve ser registrada como baixa, média ou alta Cenário 3 – Integração com ITSM Dado que houve necessidade de abertura de ticket Quando o log for persistido Então o campo Incidente/Requisição deve conter a referência correspondente 🧪 Cenários de Teste de Validação Pré-condições Middleware em funcionamento Mecanismo de persistência disponível Passos Gerar um evento no middleware Informar Caso de Uso e Criticidade Associar um ticket de Incidente/Requisição (quando aplicável) Resultados Esperados Log persistido corretamente Campos preenchidos conforme definido Registro disponível para auditoria e análise ❌ Cenários de Teste de Rejeição Persistência do log sem Status Persistência do log sem identificação do Caso de Uso Registro de criticidade fora dos valores permitidos (baixa, média, alta) Registro inconsistente entre evento e referência de Incidente/Requisição 🔄 Cenários de Teste de Regressão Execução de fluxos existentes do middleware sem impacto de performance perceptível Processamento normal das integrações após ativação da persistência de logs Ausência de falhas ou indisponibilidade causada pelo novo mecanismo 🧭 Sugestão de Cutover Comunicação às equipes de AMS e Governança sobre o novo padrão de logs Validação em ambiente produtivo com eventos controlados Monitoramento inicial pós-implantação Disponibilização de evidências para auditoria | S7: 8 | T7: =_xlfn.XLOOKUP(S7,Tabela4[Horas],Tabela4[Pontos],,1) | U7: ENS-9944 | V7: ENS-10734 | W7: ENS-10735 | Y7: =HYPERLINK("https://tkebrasil.atlassian.net/browse/" & U7,U7) | Z7: =HYPERLINK("https://tkebrasil.atlassian.net/browse/" & V7,V7) | AA7: =HYPERLINK("https://tkebrasil.atlassian.net/browse/" & W7,W7) | AC7: X | AD7: BL | AE7: =IF($AD7=AE$1,$U7) | AF7: =IF($AD7=AF$1,$U7) | AG7: =IF($AD7=AG$1,$U7) | AH7: =IF($AD7=AH$1,$V7) | AI7: =IF($AD7=AI$1,$V7) | AJ7: =IF($AD7=AJ$1,$V7) | AK7: =IF($AD7=AK$1,$W7) | AL7: =IF($AD7=AL$1,$W7) | AM7: =IF($AD7=AM$1,$W7)
A8: =UPPER(LEFT(I8, 3)) | B8: 2026-08-10 | C8: 0 | D8: 0 | F8: 0 | G8: INTERFACE | H8: NOVO DESENVOLVIMENTO | I8: ensemble@thyssenkruppelevadores.com.br | J8: Giovani Perotto Mesquita | K8: =_xlfn.XLOOKUP(Planilha!$J8,Tabela9[Pessoas],Tabela9[UUID Jira]) | L8: Regina Albanus | M8: =_xlfn.XLOOKUP(Planilha!$L8,Tabela9[Pessoas],Tabela9[UUID Jira]) | N8: Alterar logs do IRIS para tabela federada | O8: Alterar logs do IRIS para tabela federada 2 | P8: Alterar logs do IRIS para tabela federada 2 | Q8: Implementação | R8: ✅ User Story 1 — Persistência Estruturada de Logs de Auditoria 🧾 Requisito Definido Implementar mecanismo de persistência estruturada para logs de auditoria do middleware, garantindo rastreabilidade, governança operacional e suporte aos processos de ITSM (ITIL). Os registros deverão contemplar, no mínimo, os seguintes atributos: Status: classificação do registro conforme análise do AMS (Application Management Services), indicando o estado operacional, tratamento ou encaminhamento do evento; UC – Caso de Uso: identificação do uso de caso ou fluxo de negócio associado ao registro, viabilizando rastreabilidade ponta a ponta para fins de auditoria e investigação; Criticidade: nível de impacto do evento (baixa, média ou alta), suportando priorização operacional e gestão de incidentes; Incidente/Requisição: referência ao incidente ou requisição registrada no sistema de ITSM, quando houver necessidade de abertura de ticket, assegurando integração com os processos de Incident e Request Management. Essa persistência deverá permitir auditorias técnicas e funcionais, apoiar análises de causa raiz, além de atender requisitos de compliance, observabilidade e melhoria contínua do ambiente de integração. 🧑‍💼 Contato Giovani Mesquita – Product Owner AMS (Application Management Services) Equipe de Middleware / Integração Governança de TI / ITSM 📖 Título da User Story Como Product Owner, quero que o middleware persista logs de auditoria de forma estruturada, para que seja possível garantir rastreabilidade, governança operacional e suporte aos processos de ITSM. 📊 Priorização Alta Justificativa: Alto valor para compliance, auditoria e governança Impacto direto na operação e no suporte (Incident/Request Management) Necessário para análise de causa raiz e melhoria contínua Dependência para processos operacionais e auditorias futuras 🔍 Processo Atual (AS IS) Atualmente, o middleware não possui um mecanismo estruturado e persistente para registro de logs de auditoria, dificultando a rastreabilidade de eventos, investigações operacionais, auditorias técnicas e integração com processos de ITSM. 🚀 Processo Futuro (TO BE) O middleware passará a registrar e persistir logs de auditoria de forma estruturada, contendo informações essenciais para análise operacional, auditoria e governança, permitindo integração com processos de Incident e Request Management. 🎯 Objetivo da Mudança Garantir rastreabilidade ponta a ponta dos eventos do middleware Apoiar auditorias técnicas e funcionais Facilitar análises de causa raiz Suportar compliance, observabilidade e melhoria contínua Integrar os eventos do middleware aos processos de ITSM ❌ Fora de Escopo Criação ou customização do sistema de ITSM Dashboards analíticos ou relatórios avançados Automação de abertura de tickets Retenção histórica além do definido pelo middleware ✅ Critérios de Aceitação (BDD) Cenário 1 – Persistência correta dos logs Dado que um evento ocorre no middleware Quando o log de auditoria é registrado Então o registro deve ser persistido contendo Status, Caso de Uso, Criticidade e referência a Incidente/Requisição (quando aplicável) Cenário 2 – Registro de criticidade Dado um evento com impacto operacional Quando o log é persistido Então a criticidade deve ser registrada como baixa, média ou alta Cenário 3 – Integração com ITSM Dado que houve necessidade de abertura de ticket Quando o log for persistido Então o campo Incidente/Requisição deve conter a referência correspondente 🧪 Cenários de Teste de Validação Pré-condições Middleware em funcionamento Mecanismo de persistência disponível Passos Gerar um evento no middleware Informar Caso de Uso e Criticidade Associar um ticket de Incidente/Requisição (quando aplicável) Resultados Esperados Log persistido corretamente Campos preenchidos conforme definido Registro disponível para auditoria e análise ❌ Cenários de Teste de Rejeição Persistência do log sem Status Persistência do log sem identificação do Caso de Uso Registro de criticidade fora dos valores permitidos (baixa, média, alta) Registro inconsistente entre evento e referência de Incidente/Requisição 🔄 Cenários de Teste de Regressão Execução de fluxos existentes do middleware sem impacto de performance perceptível Processamento normal das integrações após ativação da persistência de logs Ausência de falhas ou indisponibilidade causada pelo novo mecanismo 🧭 Sugestão de Cutover Comunicação às equipes de AMS e Governança sobre o novo padrão de logs Validação em ambiente produtivo com eventos controlados Monitoramento inicial pós-implantação Disponibilização de evidências para auditoria | S8: 2 | T8: =_xlfn.XLOOKUP(S8,Tabela4[Horas],Tabela4[Pontos],,1) | U8: ENS-9944 | V8: ENS-10736 | W8: ENS-10737 | Y8: =HYPERLINK("https://tkebrasil.atlassian.net/browse/" & U8,U8) | Z8: =HYPERLINK("https://tkebrasil.atlassian.net/browse/" & V8,V8) | AA8: =HYPERLINK("https://tkebrasil.atlassian.net/browse/" & W8,W8) | AC8: X | AD8: BL | AE8: =IF($AD8=AE$1,$U8) | AF8: =IF($AD8=AF$1,$U8) | AG8: =IF($AD8=AG$1,$U8) | AH8: =IF($AD8=AH$1,$V8) | AI8: =IF($AD8=AI$1,$V8) | AJ8: =IF($AD8=AJ$1,$V8) | AK8: =IF($AD8=AK$1,$W8) | AL8: =IF($AD8=AL$1,$W8) | AM8: =IF($AD8=AM$1,$W8)
A9: =UPPER(LEFT(I9, 3)) | B9: 2026-08-10 | C9: 0 | D9: 0 | F9: 0 | G9: INTERFACE | H9: NOVO DESENVOLVIMENTO | I9: ensemble@thyssenkruppelevadores.com.br | J9: Giovani Perotto Mesquita | K9: =_xlfn.XLOOKUP(Planilha!$J9,Tabela9[Pessoas],Tabela9[UUID Jira]) | L9: Pablo Rocha | M9: =_xlfn.XLOOKUP(Planilha!$L9,Tabela9[Pessoas],Tabela9[UUID Jira]) | N9: Alterar logs do IRIS para tabela federada | O9: Alterar logs do IRIS para tabela federada 3 | P9: Alterar logs do IRIS para tabela federada 3 | Q9: Implementação | R9: ✅ User Story 1 — Persistência Estruturada de Logs de Auditoria 🧾 Requisito Definido Implementar mecanismo de persistência estruturada para logs de auditoria do middleware, garantindo rastreabilidade, governança operacional e suporte aos processos de ITSM (ITIL). Os registros deverão contemplar, no mínimo, os seguintes atributos: Status: classificação do registro conforme análise do AMS (Application Management Services), indicando o estado operacional, tratamento ou encaminhamento do evento; UC – Caso de Uso: identificação do uso de caso ou fluxo de negócio associado ao registro, viabilizando rastreabilidade ponta a ponta para fins de auditoria e investigação; Criticidade: nível de impacto do evento (baixa, média ou alta), suportando priorização operacional e gestão de incidentes; Incidente/Requisição: referência ao incidente ou requisição registrada no sistema de ITSM, quando houver necessidade de abertura de ticket, assegurando integração com os processos de Incident e Request Management. Essa persistência deverá permitir auditorias técnicas e funcionais, apoiar análises de causa raiz, além de atender requisitos de compliance, observabilidade e melhoria contínua do ambiente de integração. 🧑‍💼 Contato Giovani Mesquita – Product Owner AMS (Application Management Services) Equipe de Middleware / Integração Governança de TI / ITSM 📖 Título da User Story Como Product Owner, quero que o middleware persista logs de auditoria de forma estruturada, para que seja possível garantir rastreabilidade, governança operacional e suporte aos processos de ITSM. 📊 Priorização Alta Justificativa: Alto valor para compliance, auditoria e governança Impacto direto na operação e no suporte (Incident/Request Management) Necessário para análise de causa raiz e melhoria contínua Dependência para processos operacionais e auditorias futuras 🔍 Processo Atual (AS IS) Atualmente, o middleware não possui um mecanismo estruturado e persistente para registro de logs de auditoria, dificultando a rastreabilidade de eventos, investigações operacionais, auditorias técnicas e integração com processos de ITSM. 🚀 Processo Futuro (TO BE) O middleware passará a registrar e persistir logs de auditoria de forma estruturada, contendo informações essenciais para análise operacional, auditoria e governança, permitindo integração com processos de Incident e Request Management. 🎯 Objetivo da Mudança Garantir rastreabilidade ponta a ponta dos eventos do middleware Apoiar auditorias técnicas e funcionais Facilitar análises de causa raiz Suportar compliance, observabilidade e melhoria contínua Integrar os eventos do middleware aos processos de ITSM ❌ Fora de Escopo Criação ou customização do sistema de ITSM Dashboards analíticos ou relatórios avançados Automação de abertura de tickets Retenção histórica além do definido pelo middleware ✅ Critérios de Aceitação (BDD) Cenário 1 – Persistência correta dos logs Dado que um evento ocorre no middleware Quando o log de auditoria é registrado Então o registro deve ser persistido contendo Status, Caso de Uso, Criticidade e referência a Incidente/Requisição (quando aplicável) Cenário 2 – Registro de criticidade Dado um evento com impacto operacional Quando o log é persistido Então a criticidade deve ser registrada como baixa, média ou alta Cenário 3 – Integração com ITSM Dado que houve necessidade de abertura de ticket Quando o log for persistido Então o campo Incidente/Requisição deve conter a referência correspondente 🧪 Cenários de Teste de Validação Pré-condições Middleware em funcionamento Mecanismo de persistência disponível Passos Gerar um evento no middleware Informar Caso de Uso e Criticidade Associar um ticket de Incidente/Requisição (quando aplicável) Resultados Esperados Log persistido corretamente Campos preenchidos conforme definido Registro disponível para auditoria e análise ❌ Cenários de Teste de Rejeição Persistência do log sem Status Persistência do log sem identificação do Caso de Uso Registro de criticidade fora dos valores permitidos (baixa, média, alta) Registro inconsistente entre evento e referência de Incidente/Requisição 🔄 Cenários de Teste de Regressão Execução de fluxos existentes do middleware sem impacto de performance perceptível Processamento normal das integrações após ativação da persistência de logs Ausência de falhas ou indisponibilidade causada pelo novo mecanismo 🧭 Sugestão de Cutover Comunicação às equipes de AMS e Governança sobre o novo padrão de logs Validação em ambiente produtivo com eventos controlados Monitoramento inicial pós-implantação Disponibilização de evidências para auditoria | S9: 8 | T9: =_xlfn.XLOOKUP(S9,Tabela4[Horas],Tabela4[Pontos],,1) | U9: ENS-9944 | V9: ENS-10738 | W9: ENS-10739 | Y9: =HYPERLINK("https://tkebrasil.atlassian.net/browse/" & U9,U9) | Z9: =HYPERLINK("https://tkebrasil.atlassian.net/browse/" & V9,V9) | AA9: =HYPERLINK("https://tkebrasil.atlassian.net/browse/" & W9,W9) | AC9: X | AD9: BL | AE9: =IF($AD9=AE$1,$U9) | AF9: =IF($AD9=AF$1,$U9) | AG9: =IF($AD9=AG$1,$U9) | AH9: =IF($AD9=AH$1,$V9) | AI9: =IF($AD9=AI$1,$V9) | AJ9: =IF($AD9=AJ$1,$V9) | AK9: =IF($AD9=AK$1,$W9) | AL9: =IF($AD9=AL$1,$W9) | AM9: =IF($AD9=AM$1,$W9)
A10: =UPPER(LEFT(I10, 3)) | B10: 2026-08-10 | C10: CR AP Summary | D10: CR AP Summary | F10: 0 | G10: INTERFACE | H10: NOVO DESENVOLVIMENTO | I10: ensemble@thyssenkruppelevadores.com.br | J10: Giovani Perotto Mesquita | K10: =_xlfn.XLOOKUP(Planilha!$J10,Tabela9[Pessoas],Tabela9[UUID Jira]) | L10: Regina Albanus | M10: =_xlfn.XLOOKUP(Planilha!$L10,Tabela9[Pessoas],Tabela9[UUID Jira]) | N10: Alteração da interface Sincrona para Assincrona do AP Summary | O10: Alteração da interface Sincrona para Assincrona do AP Summary | P10: Alteração da interface Sincrona para Assincrona do AP Summary | Q10: Execução de Testes | R10: Conforme CR do projeto AP Summary | S10: 2 | T10: =_xlfn.XLOOKUP(S10,Tabela4[Horas],Tabela4[Pontos],,1) | U10: ENS-9951 | V10: ENS-10740 | W10: ENS-10741 | Y10: =HYPERLINK("https://tkebrasil.atlassian.net/browse/" & U10,U10) | Z10: =HYPERLINK("https://tkebrasil.atlassian.net/browse/" & V10,V10) | AA10: =HYPERLINK("https://tkebrasil.atlassian.net/browse/" & W10,W10) | AC10: X | AD10: BL | AE10: =IF($AD10=AE$1,$U10) | AF10: =IF($AD10=AF$1,$U10) | AG10: =IF($AD10=AG$1,$U10) | AH10: =IF($AD10=AH$1,$V10) | AI10: =IF($AD10=AI$1,$V10) | AJ10: =IF($AD10=AJ$1,$V10) | AK10: =IF($AD10=AK$1,$W10) | AL10: =IF($AD10=AL$1,$W10) | AM10: =IF($AD10=AM$1,$W10)
A11: =UPPER(LEFT(I11, 3)) | B11: 2026-08-10 | C11: REQ0505088 | D11: SCTASK0704281 | F11: 0 | G11: INTERFACE | H11: ALTERAÇÃO | I11: ensemble@thyssenkruppelevadores.com.br | J11: Giovani Perotto Mesquita | K11: =_xlfn.XLOOKUP(Planilha!$J11,Tabela9[Pessoas],Tabela9[UUID Jira]) | L11: Luiz Felipe Brandão da Silva | M11: =_xlfn.XLOOKUP(Planilha!$L11,Tabela9[Pessoas],Tabela9[UUID Jira]) | N11: Alterar na interface PosicaoFinanceira.ContratosContatos para que tivermos erro interno do IRIS, mandar uma mensagem | O11: Alterar na interface PosicaoFinanceira.ContratosContatos para que tivermos erro interno do IRIS, mandar uma mensagem | P11: Alterar na interface PosicaoFinanceira.ContratosContatos para que tivermos erro interno do IRIS, mandar uma mensagem | Q11: Execução de Testes | R11: Alterar na interface PosicaoFinanceira.ContratosContatos para que tivermos erro interno do IRIS, mandar uma mensagem. PO - Marco Gross | S11: 2 | T11: =_xlfn.XLOOKUP(S11,Tabela4[Horas],Tabela4[Pontos],,1) | U11: ENS-9954 | V11: ENS-10742 | W11: ENS-10743 | Y11: =HYPERLINK("https://tkebrasil.atlassian.net/browse/" & U11,U11) | Z11: =HYPERLINK("https://tkebrasil.atlassian.net/browse/" & V11,V11) | AA11: =HYPERLINK("https://tkebrasil.atlassian.net/browse/" & W11,W11) | AC11: X | AD11: BL | AE11: =IF($AD11=AE$1,$U11) | AF11: =IF($AD11=AF$1,$U11) | AG11: =IF($AD11=AG$1,$U11) | AH11: =IF($AD11=AH$1,$V11) | AI11: =IF($AD11=AI$1,$V11) | AJ11: =IF($AD11=AJ$1,$V11) | AK11: =IF($AD11=AK$1,$W11) | AL11: =IF($AD11=AL$1,$W11) | AM11: =IF($AD11=AM$1,$W11)
A12: =UPPER(LEFT(I12, 3)) | B12: 2026-08-10 | C12: REQ0396346 | D12: SCTASK0592786 | F12: 0 | G12: INTERFACE | H12: ALTERAÇÃO | I12: ensemble@thyssenkruppelevadores.com.br | J12: Giovani Perotto Mesquita | K12: =_xlfn.XLOOKUP(Planilha!$J12,Tabela9[Pessoas],Tabela9[UUID Jira]) | L12: Pablo Rocha | M12: =_xlfn.XLOOKUP(Planilha!$L12,Tabela9[Pessoas],Tabela9[UUID Jira]) | N12: Criar e disponibilizar um novo campo denominado “Preço Max” na transação ZV75 do SAP, garantindo que o valor de reajuste em contratos PRICING seja enviado de forma segregada (Preço de Manutenção e Preço Max) para permitir o correto tratamento no GUS e alinhamento das linhas CMAX no SAP, por meio do fluxo de integração SAP → IRIS → GUS. | O12: Criar e disponibilizar um novo campo denominado “Preço Max” na transação ZV75 do SAP, garantindo que o valor de reajuste em contratos PRICING seja enviado de forma segregada (Preço de Manutenção e Preço Max) para permitir o correto tratamento no GUS e alinhamento das linhas CMAX no SAP, por meio do fluxo de integração SAP → IRIS → GUS. | P12: Criar e disponibilizar um novo campo denominado “Preço Max” na transação ZV75 do SAP, garantindo que o valor de reajuste em contratos PRICING seja enviado de forma segregada (Preço de Manutenção e Preço Max) para permitir o correto tratamento no GUS e alinhamento das linhas CMAX no SAP, por meio do fluxo de integração SAP → IRIS → GUS. | Q12: Execução de Testes | R12: 🧾 Defined Requirement Criar e disponibilizar um novo campo denominado “Preço Max” na transação ZV75 do SAP, garantindo que o valor de reajuste em contratos PRICING seja enviado de forma segregada (Preço de Manutenção e Preço Max) para permitir o correto tratamento no GUS e alinhamento das linhas CMAX no SAP, por meio do fluxo de integração SAP → IRIS → GUS. 🧑‍💼 Contact João Mateus – Product Owner SAP Stephanie - Product Owner GUS Equipe SAP Equipe IRIS Equipe GUS Gabriel Kramer – Stakeholder (reunião prévia) Fernanda Gelatti – Stakeholder (reunião prévia) 📖 User Story Title As a Analista de Negócio, I want que o SAP envie separadamente os valores de Preço de Manutenção e Preço Max, so that os contratos PRICING sejam ajustados corretamente no GUS e alinhem as linhas CMAX no SAP. 📊 Prioritization Priority: High Justificativa: Business value: Permite cálculo correto de reajustes contratuais PRICING. Impacto: Impede inconsistências financeiras e retrabalho manual. Urgência: Situação atual bloqueia ajustes corretos no GUS. Dependências: Integração direta entre SAP, IRIS e GUS. 🔍 Current Process (AS IS) Atualmente, o SAP envia um único valor de reajuste, sem separação entre Preço de Manutenção e Preço Max. Esse modelo impossibilita: Ajuste correto das tabelas no GUS Alinhamento das linhas CMAX no SAP 🚀 Future Process (TO BE) O SAP passa a disponibilizar um novo campo “Preço Max” na ZV75, enviando: Preço de Manutenção Preço Max O IRIS atualiza o arquivo de integração e o GUS recebe os valores de forma segregada, aplicando corretamente os ajustes conforme a regra de negócio. 🎯 Change Objective Garantir conformidade contratual e correto tratamento financeiro dos contratos PRICING, eliminando inconsistências e dependência de ajustes manuais. ❌ Out of Scope Alterações em tipos contratuais que não sejam PRICING Revisão de regras de cálculo no GUS além do consumo do novo campo Mudanças retroativas em contratos já encerrados ✅ Acceptance Criteria (BDD) Scenario 1 – Envio correto dos valores segregados Given que existe um contrato do tipo PRICING no SAP When o reajuste contratual for processado Then o SAP deve enviar separadamente os campos “Preço de Manutenção” e “Preço Max” para o IRIS And o GUS deve receber ambos os valores de forma estruturada Scenario 2 – Campo obrigatório Given um contrato PRICING When o campo “Preço Max” não estiver preenchido Then o contrato não deve ser enviado para integração 🧪 Validation Test Scenarios Cenário 1 – Fluxo completo SAP → IRIS → GUS Precondições: Contrato PRICING ativo no SAP Passos: Informar Preço de Manutenção Informar Preço Max na ZV75 Executar integração Resultado Esperado: Ambos os valores recebidos corretamente no GUS ❌ Rejection Test Scenarios Cenário – Envio de valor único Situação: SAP envia apenas um valor consolidado Resultado Esperado: Integração rejeitada ou sinalizada como incorreta GUS não aplica ajuste 🔄 Regression Test Scenarios Cenário – Contratos não PRICING Verificação: Contratos de outros tipos continuam funcionando sem impacto Resultado Esperado: Nenhuma alteração nos fluxos existentes 🧭 Cutover Suggestion Comunicação aos times SAP, IRIS e GUS sobre o novo campo Atualização do layout de integração Testes integrados em ambiente controlado Liberação coordenada em produção 📈 Score (GUT) CritérioNotaGravity (Gravidade)5Urgency (Urgência)4Trend (Tendência)4GUT Total80 | S12: 2 | T12: =_xlfn.XLOOKUP(S12,Tabela4[Horas],Tabela4[Pontos],,1) | U12: ENS-9957 | V12: ENS-10744 | W12: ENS-10745 | Y12: =HYPERLINK("https://tkebrasil.atlassian.net/browse/" & U12,U12) | Z12: =HYPERLINK("https://tkebrasil.atlassian.net/browse/" & V12,V12) | AA12: =HYPERLINK("https://tkebrasil.atlassian.net/browse/" & W12,W12) | AC12: X | AD12: BL | AE12: =IF($AD12=AE$1,$U12) | AF12: =IF($AD12=AF$1,$U12) | AG12: =IF($AD12=AG$1,$U12) | AH12: =IF($AD12=AH$1,$V12) | AI12: =IF($AD12=AI$1,$V12) | AJ12: =IF($AD12=AJ$1,$V12) | AK12: =IF($AD12=AK$1,$W12) | AL12: =IF($AD12=AL$1,$W12) | AM12: =IF($AD12=AM$1,$W12)
A13: =UPPER(LEFT(I13, 3)) | B13: 2026-08-10 | C13: 0 | D13: 0 | F13: 0 | G13: INTERFACE | H13: NOVO DESENVOLVIMENTO | I13: ensemble@thyssenkruppelevadores.com.br | J13: Giovani Perotto Mesquita | K13: =_xlfn.XLOOKUP(Planilha!$J13,Tabela9[Pessoas],Tabela9[UUID Jira]) | L13: Regina Albanus | M13: =_xlfn.XLOOKUP(Planilha!$L13,Tabela9[Pessoas],Tabela9[UUID Jira]) | N13: Preparo de CAB 2 | O13: Preparo de CAB 2 | P13: Preparo de CAB 2 | Q13: Análise Técnica | R13: **OBJETIVO GERAL** [Descreva o objetivo geral da alteração] **ITENS A SEREM ATENDIDOS:** **1. [Item 1]** **1.1. Tipo de Funcionalidade:** [Informar o tipo de funcionalidade] **1.2. Complexidade:** [Alta, Média, Baixa, etc] **1.3. Protótipo de Tela:** [Informações a respeito do protótipo da tela] **1.4. Critérios de Validação:** a. [Critério de validação 1] b. [Critério de validação 2] | S13: 4 | T13: =_xlfn.XLOOKUP(S13,Tabela4[Horas],Tabela4[Pontos],,1) | U13: ENS-9632 | V13: ENS-10746 | W13: ENS-10747 | Y13: =HYPERLINK("https://tkebrasil.atlassian.net/browse/" & U13,U13) | Z13: =HYPERLINK("https://tkebrasil.atlassian.net/browse/" & V13,V13) | AA13: =HYPERLINK("https://tkebrasil.atlassian.net/browse/" & W13,W13) | AC13: X | AD13: BL | AE13: =IF($AD13=AE$1,$U13) | AF13: =IF($AD13=AF$1,$U13) | AG13: =IF($AD13=AG$1,$U13) | AH13: =IF($AD13=AH$1,$V13) | AI13: =IF($AD13=AI$1,$V13) | AJ13: =IF($AD13=AJ$1,$V13) | AK13: =IF($AD13=AK$1,$W13) | AL13: =IF($AD13=AL$1,$W13) | AM13: =IF($AD13=AM$1,$W13)
A14: =UPPER(LEFT(I14, 3)) | B14: 2026-08-10 | C14: 0 | D14: 0 | F14: 0 | G14: INTERFACE | H14: NOVO DESENVOLVIMENTO | I14: ensemble@thyssenkruppelevadores.com.br | J14: Giovani Perotto Mesquita | K14: =_xlfn.XLOOKUP(Planilha!$J14,Tabela9[Pessoas],Tabela9[UUID Jira]) | L14: Luiz Felipe Brandão da Silva | M14: =_xlfn.XLOOKUP(Planilha!$L14,Tabela9[Pessoas],Tabela9[UUID Jira]) | N14: Preparo de CAB 4 | O14: Preparo de CAB 4 | P14: Preparo de CAB 4 | Q14: Análise Técnica | R14: **OBJETIVO GERAL** [Descreva o objetivo geral da alteração] **ITENS A SEREM ATENDIDOS:** **1. [Item 1]** **1.1. Tipo de Funcionalidade:** [Informar o tipo de funcionalidade] **1.2. Complexidade:** [Alta, Média, Baixa, etc] **1.3. Protótipo de Tela:** [Informações a respeito do protótipo da tela] **1.4. Critérios de Validação:** a. [Critério de validação 1] b. [Critério de validação 2] | S14: 4 | T14: =_xlfn.XLOOKUP(S14,Tabela4[Horas],Tabela4[Pontos],,1) | U14: ENS-9635 | V14: ENS-10748 | W14: ENS-10749 | Y14: =HYPERLINK("https://tkebrasil.atlassian.net/browse/" & U14,U14) | Z14: =HYPERLINK("https://tkebrasil.atlassian.net/browse/" & V14,V14) | AA14: =HYPERLINK("https://tkebrasil.atlassian.net/browse/" & W14,W14) | AC14: X | AD14: BL | AE14: =IF($AD14=AE$1,$U14) | AF14: =IF($AD14=AF$1,$U14) | AG14: =IF($AD14=AG$1,$U14) | AH14: =IF($AD14=AH$1,$V14) | AI14: =IF($AD14=AI$1,$V14) | AJ14: =IF($AD14=AJ$1,$V14) | AK14: =IF($AD14=AK$1,$W14) | AL14: =IF($AD14=AL$1,$W14) | AM14: =IF($AD14=AM$1,$W14)
A15: =UPPER(LEFT(I15, 3)) | B15: 2026-08-10 | C15: REQ0522963 | D15: SCTASK0727583 | F15: 0 | G15: INTERFACE | H15: NOVO DESENVOLVIMENTO | I15: ensemble@thyssenkruppelevadores.com.br | J15: Giovani Perotto Mesquita | K15: =_xlfn.XLOOKUP(Planilha!$J15,Tabela9[Pessoas],Tabela9[UUID Jira]) | L15: Luiz Felipe Brandão da Silva | M15: =_xlfn.XLOOKUP(Planilha!$L15,Tabela9[Pessoas],Tabela9[UUID Jira]) | N15: Criar alerta quando mensagem da Adobe chegar no webhook | O15: Criar alerta quando mensagem da Adobe chegar no webhook | P15: Criar alerta quando mensagem da Adobe chegar no webhook | Q15: Execução de Testes | R15: **OBJETIVO GERAL** [Descreva o objetivo geral da alteração] **ITENS A SEREM ATENDIDOS:** **1. [Item 1]** **1.1. Tipo de Funcionalidade:** [Informar o tipo de funcionalidade] **1.2. Complexidade:** [Alta, Média, Baixa, etc] **1.3. Protótipo de Tela:** [Informações a respeito do protótipo da tela] **1.4. Critérios de Validação:** a. [Critério de validação 1] b. [Critério de validação 2] | S15: 2 | T15: =_xlfn.XLOOKUP(S15,Tabela4[Horas],Tabela4[Pontos],,1) | U15: ENS-10442 | V15: ENS-10750 | W15: ENS-10751 | Y15: =HYPERLINK("https://tkebrasil.atlassian.net/browse/" & U15,U15) | Z15: =HYPERLINK("https://tkebrasil.atlassian.net/browse/" & V15,V15) | AA15: =HYPERLINK("https://tkebrasil.atlassian.net/browse/" & W15,W15) | AC15: X | AD15: BL | AE15: =IF($AD15=AE$1,$U15) | AF15: =IF($AD15=AF$1,$U15) | AG15: =IF($AD15=AG$1,$U15) | AH15: =IF($AD15=AH$1,$V15) | AI15: =IF($AD15=AI$1,$V15) | AJ15: =IF($AD15=AJ$1,$V15) | AK15: =IF($AD15=AK$1,$W15) | AL15: =IF($AD15=AL$1,$W15) | AM15: =IF($AD15=AM$1,$W15)
A16: =UPPER(LEFT(I16, 3)) | B16: 2026-08-10 | C16: REQ0522901 | D16: SCTASK0727520 | F16: 0 | G16: INTERFACE | H16: NOVO DESENVOLVIMENTO | I16: ensemble@thyssenkruppelevadores.com.br | J16: Giovani Perotto Mesquita | K16: =_xlfn.XLOOKUP(Planilha!$J16,Tabela9[Pessoas],Tabela9[UUID Jira]) | L16: Regina Albanus | M16: =_xlfn.XLOOKUP(Planilha!$L16,Tabela9[Pessoas],Tabela9[UUID Jira]) | N16: Implementar API Soluti timestamp | O16: Implementar API Soluti timestamp | P16: Implementar API Soluti timestamp | Q16: Análise Técnica | R16: **OBJETIVO GERAL** [Descreva o objetivo geral da alteração] **ITENS A SEREM ATENDIDOS:** **1. [Item 1]** **1.1. Tipo de Funcionalidade:** [Informar o tipo de funcionalidade] **1.2. Complexidade:** [Alta, Média, Baixa, etc] **1.3. Protótipo de Tela:** [Informações a respeito do protótipo da tela] **1.4. Critérios de Validação:** a. [Critério de validação 1] b. [Critério de validação 2] | S16: 8 | T16: =_xlfn.XLOOKUP(S16,Tabela4[Horas],Tabela4[Pontos],,1) | U16: ENS-10362 | V16: ENS-10752 | W16: ENS-10753 | Y16: =HYPERLINK("https://tkebrasil.atlassian.net/browse/" & U16,U16) | Z16: =HYPERLINK("https://tkebrasil.atlassian.net/browse/" & V16,V16) | AA16: =HYPERLINK("https://tkebrasil.atlassian.net/browse/" & W16,W16) | AC16: X | AD16: BL | AE16: =IF($AD16=AE$1,$U16) | AF16: =IF($AD16=AF$1,$U16) | AG16: =IF($AD16=AG$1,$U16) | AH16: =IF($AD16=AH$1,$V16) | AI16: =IF($AD16=AI$1,$V16) | AJ16: =IF($AD16=AJ$1,$V16) | AK16: =IF($AD16=AK$1,$W16) | AL16: =IF($AD16=AL$1,$W16) | AM16: =IF($AD16=AM$1,$W16)
A17: =UPPER(LEFT(I17, 3)) | B17: 2026-08-10 | C17: REQ0482512 | D17: SCTASK0708892 | F17: 0 | G17: INTERFACE | H17: NOVO DESENVOLVIMENTO | I17: ensemble@thyssenkruppelevadores.com.br | J17: Giovani Perotto Mesquita | K17: =_xlfn.XLOOKUP(Planilha!$J17,Tabela9[Pessoas],Tabela9[UUID Jira]) | L17: Pablo Rocha | M17: =_xlfn.XLOOKUP(Planilha!$L17,Tabela9[Pessoas],Tabela9[UUID Jira]) | N17: Enviar CPF via jspv | O17: Enviar CPF via jspv | P17: Enviar CPF via jspv | Q17: Análise Técnica | R17: Demanda da Stephanie, segunda a mesma seria só incluir este campo | S17: 4 | T17: =_xlfn.XLOOKUP(S17,Tabela4[Horas],Tabela4[Pontos],,1) | U17: ENS-10576 | V17: ENS-10754 | W17: ENS-10755 | Y17: =HYPERLINK("https://tkebrasil.atlassian.net/browse/" & U17,U17) | Z17: =HYPERLINK("https://tkebrasil.atlassian.net/browse/" & V17,V17) | AA17: =HYPERLINK("https://tkebrasil.atlassian.net/browse/" & W17,W17) | AC17: X | AD17: BL | AE17: =IF($AD17=AE$1,$U17) | AF17: =IF($AD17=AF$1,$U17) | AG17: =IF($AD17=AG$1,$U17) | AH17: =IF($AD17=AH$1,$V17) | AI17: =IF($AD17=AI$1,$V17) | AJ17: =IF($AD17=AJ$1,$V17) | AK17: =IF($AD17=AK$1,$W17) | AL17: =IF($AD17=AL$1,$W17) | AM17: =IF($AD17=AM$1,$W17)
A18: =UPPER(LEFT(I18, 3)) | B18: 2026-08-10 | C18: REQ0526341 | D18: SCTASK0744373 | F18: 0 | G18: INTERFACE | H18: NOVO DESENVOLVIMENTO | I18: ensemble@thyssenkruppelevadores.com.br | J18: Giovani Perotto Mesquita | K18: =_xlfn.XLOOKUP(Planilha!$J18,Tabela9[Pessoas],Tabela9[UUID Jira]) | L18: Luiz Felipe Brandão da Silva | M18: =_xlfn.XLOOKUP(Planilha!$L18,Tabela9[Pessoas],Tabela9[UUID Jira]) | N18: Criar um fluxo de dados para capturar as informações de DOT.CALCULO provenientes do Dossiê Técnico | O18: Criar um fluxo de dados para capturar as informações de DOT.CALCULO provenientes do Dossiê Técnico | P18: Criar um fluxo de dados para capturar as informações de DOT.CALCULO provenientes do Dossiê Técnico | Q18: Análise Técnica | R18: 🧾 Definição da Necessidade Criar um fluxo de dados para capturar as informações de DOT.CALCULO provenientes do Dossiê Técnico, persistindo os dados transitados no IRIS por meio de uma tabela federada, viabilizando a disponibilidade e rastreabilidade das informações para consumo futuro. Fonte: SCTASK0744373 🧑‍💼 Contato PO: Robson Portella 📖 Título da User Story Como responsável pelo consumo de informações do Dossiê Técnico, quero que os dados de DOT.CALCULO sejam persistidos em uma tabela federada no IRIS, para que as informações transitadas possam ser armazenadas e disponibilizadas de forma estruturada para utilização posterior. 📊 Priorização Prioridade: Alta Justificativa: Valor de negócio: Permite a disponibilização estruturada dos dados do Dossiê Técnico. Impacto: Cria a base necessária para consultas e integrações futuras. Urgência: Existe uma solicitação explícita para implementação do fluxo de persistência. Dependências: A persistência em tabela federada é pré-requisito para qualquer consumo analítico ou operacional destes dados. 🔍 Processo Atual (AS IS) Os dados de DOT.CALCULO transitam pelo processo do Dossiê Técnico, porém não existe uma persistência das informações em uma tabela federada dentro do IRIS. 🚀 Processo Futuro (TO BE) Os dados de DOT.CALCULO serão capturados durante sua transitação no processo do Dossiê Técnico e persistidos automaticamente em uma tabela federada no IRIS, permitindo sua consulta e utilização por consumidores autorizados. 🎯 Objetivo da Mudança Implementar um mecanismo de persistência dos dados DOT.CALCULO em uma tabela federada no IRIS, garantindo armazenamento estruturado das informações transitadas e disponibilidade para usos futuros. ❌ Fora de Escopo Criação de dashboards ou relatórios. Desenvolvimento de consultas analíticas. Alterações na origem dos dados do Dossiê Técnico. Mudanças em sistemas consumidores. Processamento ou transformação de dados não relacionados ao objeto DOT.CALCULO. ✅ Critérios de Aceite (BDD) Cenário 1: Persistir dados recebidos Dado que existam informações de DOT.CALCULO transitando pelo processo do Dossiê Técnico Quando o fluxo de captura for executado Então os dados deverão ser persistidos em uma tabela federada no IRIS. Cenário 2: Disponibilizar dados persistidos Dado que registros tenham sido persistidos na tabela federada Quando a tabela for consultada Então os registros armazenados deverão estar disponíveis para consulta. Cenário 3: Integridade da persistência Dado que informações de DOT.CALCULO sejam processadas Quando a gravação ocorrer na tabela federada Então os dados persistidos deverão corresponder aos dados recebidos pelo fluxo. 🧪 Cenários de Teste de Validação Cenário 1: Persistência de registro válido Pré-condições Fluxo implantado. Existência de dados de DOT.CALCULO para processamento. Passos Enviar um registro contendo informações de DOT.CALCULO. Aguardar o processamento do fluxo. Consultar a tabela federada. Resultado Esperado O registro é encontrado na tabela federada do IRIS. Cenário 2: Persistência de múltiplos registros Pré-condições Fluxo operacional. Passos Processar múltiplos registros DOT.CALCULO. Consultar a tabela federada. Resultado Esperado Todos os registros processados encontram-se armazenados. Cenário 3: Disponibilidade para consulta Pré-condições Existência de registros persistidos. Passos Realizar consulta na tabela federada. Verificar retorno dos registros. Resultado Esperado Os dados persistidos são retornados corretamente. ❌ Cenários de Teste de Rejeição Cenário 1: Falha na persistência Pré-condições Fluxo executando. Passos Processar um registro DOT.CALCULO. Consultar a tabela federada. Resultado Esperado O teste falha caso o registro não seja encontrado na tabela. Cenário 2: Divergência de informações Pré-condições Registro processado. Passos Comparar os dados recebidos com os dados gravados. Validar integridade das informações. Resultado Esperado O teste falha caso existam divergências entre origem e persistência. 🔄 Cenários de Teste de Regressão Cenário 1: Continuidade do fluxo atual Pré-condições Processo existente em funcionamento. Passos Executar o processamento normal do Dossiê Técnico. Monitorar comportamento da integração. Resultado Esperado O fluxo original permanece operacional sem impactos. Cenário 2: Persistência sem interferência Pré-condições Fluxo implantado. Passos Processar registros normalmente. Validar a persistência. Validar a continuidade do processamento. Resultado Esperado A gravação na tabela federada não afeta o fluxo de origem. 🧭 Sugestão de Cutover Comunicação Informar equipes consumidoras sobre a disponibilização da nova estrutura de persistência. Implantação Publicar o fluxo de captura e persistência em ambiente produtivo. Testes em Produção Executar processamento controlado de registros DOT.CALCULO. Validar a gravação na tabela federada. Monitoramento Inicial Acompanhar o volume de registros persistidos. Verificar possíveis falhas de gravação após a entrada em produção. 📈 Score (GUT) Critério NotaGravidade 4 Urgência 4 Tendência 4 GUT = 64 Justificativa A persistência dos dados é necessária para garantir disponibilidade e rastreabilidade das informações do Dossiê Técnico. A ausência dessa estrutura pode limitar futuras consultas e integrações, justificando uma classificação elevada, embora não crítica. | S18: 8 | T18: =_xlfn.XLOOKUP(S18,Tabela4[Horas],Tabela4[Pontos],,1) | U18: ENS-10673 | V18: ENS-10756 | W18: ENS-10757 | Y18: =HYPERLINK("https://tkebrasil.atlassian.net/browse/" & U18,U18) | Z18: =HYPERLINK("https://tkebrasil.atlassian.net/browse/" & V18,V18) | AA18: =HYPERLINK("https://tkebrasil.atlassian.net/browse/" & W18,W18) | AC18: X | AD18: BL | AE18: =IF($AD18=AE$1,$U18) | AF18: =IF($AD18=AF$1,$U18) | AG18: =IF($AD18=AG$1,$U18) | AH18: =IF($AD18=AH$1,$V18) | AI18: =IF($AD18=AI$1,$V18) | AJ18: =IF($AD18=AJ$1,$V18) | AK18: =IF($AD18=AK$1,$W18) | AL18: =IF($AD18=AL$1,$W18) | AM18: =IF($AD18=AM$1,$W18)
A19: =UPPER(LEFT(I19, 3)) | B19: 2026-08-10 | C19: 0 | D19: 0 | F19: 0 | G19: INTERFACE | H19: NOVO DESENVOLVIMENTO | I19: ensemble@thyssenkruppelevadores.com.br | J19: Giovani Perotto Mesquita | K19: =_xlfn.XLOOKUP(Planilha!$J19,Tabela9[Pessoas],Tabela9[UUID Jira]) | L19: Regina Albanus | M19: =_xlfn.XLOOKUP(Planilha!$L19,Tabela9[Pessoas],Tabela9[UUID Jira]) | N19: Criar dashboard de negócios do IRIS | O19: Criar dashboard de negócios do IRIS | P19: Criar dashboard de negócios do IRIS | Q19: Análise Técnica | R19: Ver DoR | S19: 2 | T19: =_xlfn.XLOOKUP(S19,Tabela4[Horas],Tabela4[Pontos],,1) | U19: ENS-10676 | V19: ENS-10758 | W19: ENS-10759 | Y19: =HYPERLINK("https://tkebrasil.atlassian.net/browse/" & U19,U19) | Z19: =HYPERLINK("https://tkebrasil.atlassian.net/browse/" & V19,V19) | AA19: =HYPERLINK("https://tkebrasil.atlassian.net/browse/" & W19,W19) | AC19: X | AD19: BL | AE19: =IF($AD19=AE$1,$U19) | AF19: =IF($AD19=AF$1,$U19) | AG19: =IF($AD19=AG$1,$U19) | AH19: =IF($AD19=AH$1,$V19) | AI19: =IF($AD19=AI$1,$V19) | AJ19: =IF($AD19=AJ$1,$V19) | AK19: =IF($AD19=AK$1,$W19) | AL19: =IF($AD19=AL$1,$W19) | AM19: =IF($AD19=AM$1,$W19)
A20: =UPPER(LEFT(I20, 3)) | B20: 2026-08-10 | C20: REQ0525598 | D20: SCTASK0730907 | F20: 0 | G20: INTERFACE | H20: NOVO DESENVOLVIMENTO | I20: ensemble@thyssenkruppelevadores.com.br | J20: Giovani Perotto Mesquita | K20: =_xlfn.XLOOKUP(Planilha!$J20,Tabela9[Pessoas],Tabela9[UUID Jira]) | L20: Pablo Rocha | M20: =_xlfn.XLOOKUP(Planilha!$L20,Tabela9[Pessoas],Tabela9[UUID Jira]) | N20: Criar e parametrizar IOT Dynamox | O20: Criar e parametrizar IOT Dynamox | P20: Criar e parametrizar IOT Dynamox | Q20: Implementação | R20: Criar e parametrizar IOT Dynamox | S20: 6 | T20: =_xlfn.XLOOKUP(S20,Tabela4[Horas],Tabela4[Pontos],,1) | U20: ENS-10380 | V20: ENS-10760 | W20: ENS-10761 | Y20: =HYPERLINK("https://tkebrasil.atlassian.net/browse/" & U20,U20) | Z20: =HYPERLINK("https://tkebrasil.atlassian.net/browse/" & V20,V20) | AA20: =HYPERLINK("https://tkebrasil.atlassian.net/browse/" & W20,W20) | AC20: X | AD20: BL | AE20: =IF($AD20=AE$1,$U20) | AF20: =IF($AD20=AF$1,$U20) | AG20: =IF($AD20=AG$1,$U20) | AH20: =IF($AD20=AH$1,$V20) | AI20: =IF($AD20=AI$1,$V20) | AJ20: =IF($AD20=AJ$1,$V20) | AK20: =IF($AD20=AK$1,$W20) | AL20: =IF($AD20=AL$1,$W20) | AM20: =IF($AD20=AM$1,$W20)
A21: =UPPER(LEFT(I21, 3)) | B21: 2026-08-10 | C21: REQ0305661 | D21: SCTASK0489536 | F21: 0 | G21: INTERFACE | H21: NOVO DESENVOLVIMENTO | I21: ensemble@thyssenkruppelevadores.com.br | J21: Giovani Perotto Mesquita | K21: =_xlfn.XLOOKUP(Planilha!$J21,Tabela9[Pessoas],Tabela9[UUID Jira]) | L21: Regina Albanus | M21: =_xlfn.XLOOKUP(Planilha!$L21,Tabela9[Pessoas],Tabela9[UUID Jira]) | N21: Implementar a correção da informação apresentada na coluna Centro de Distribuição no relatório Mapa de Fabricação/Expedição do AIT | O21: Implementar a correção da informação apresentada na coluna Centro de Distribuição no relatório Mapa de Fabricação/Expedição do AIT | P21: Implementar a correção da informação apresentada na coluna Centro de Distribuição no relatório Mapa de Fabricação/Expedição do AIT | Q21: Análise Técnica | R21: 🧾 Requisito Definido Implementar a correção da informação apresentada na coluna Centro de Distribuição no relatório Mapa de Fabricação/Expedição do AIT, conforme necessidade identificada após alteração de lógica realizada no GUS, garantindo consistência das informações apresentadas aos usuários. 🧑‍💼 Contato Izabel Zanotelli Haas Rafael Villar Dornelles Rayanne Rosa dos Santos Tiago Fogaça 📖 Título da User Story Como usuário do relatório Mapa de Fabricação/Expedição, quero visualizar corretamente a informação da coluna Centro de Distribuição, para que os dados operacionais reflitam a lógica atual do negócio e possam ser utilizados com segurança na tomada de decisão. 📊 Priorização Prioridade: Alta Justificativa Impacta a confiabilidade dos dados apresentados aos usuários. Existe histórico de incidentes relacionados à divergência da informação. A correção depende de alinhamento entre sistemas integrados (GUS e AIT). Afeta a consistência das informações utilizadas nos processos operacionais. 🔍 Processo Atual (AS IS) Foi identificada divergência na coluna "Centro de Distribuição". A lógica de negócio foi alterada no GUS sem comunicação prévia ao AIT. Um incidente foi aberto para tratar a divergência, porém foi cancelado por se tratar de uma alteração de negócio. Existe uma alteração anterior relacionada à inclusão de novas colunas que foi desenvolvida em QA, porém nunca validada e será descartada. 🚀 Processo Futuro (TO BE) O relatório Mapa de Fabricação/Expedição deverá apresentar corretamente a informação da coluna Centro de Distribuição. A regra implementada deverá refletir a lógica atual utilizada pelo GUS. A solução será tratada por meio de solicitação formal de alteração no fluxo do AIT. Alterações não validadas anteriormente serão descartadas para evitar inconsistências no ambiente. 🎯 Objetivo da Mudança Garantir a consistência das informações do relatório Mapa de Fabricação/Expedição, eliminando divergências entre os sistemas envolvidos e aumentando a confiabilidade dos dados utilizados pelas áreas de negócio. ❌ Fora de Escopo Inclusão das duas novas colunas desenvolvidas anteriormente para o incidente 779404. Novos desenvolvimentos não relacionados à correção da coluna Centro de Distribuição. Alterações em processos não citados no documento. Evoluções funcionais em SAP, GUS ou IRIS além das explicitamente mencionadas. ✅ Critérios de Aceite (BDD) Cenário 1: Exibição correta da coluna Centro de Distribuição Dado que o usuário acessa o relatório Mapa de Fabricação/Expedição Quando consultar registros que possuam informação de Centro de Distribuição Então o valor exibido deverá refletir a regra de negócio vigente Cenário 2: Consistência dos dados Dado que existe integração de informações entre sistemas Quando os dados forem apresentados no relatório Então a informação de Centro de Distribuição deverá estar consistente com a origem definida pela regra de negócio Cenário 3: Descarte das alterações não aprovadas Dado que existem alterações desenvolvidas em QA referentes ao incidente 779404 Quando a entrega for promovida Então as alterações não validadas deverão permanecer descartadas 🧪 Cenários de Teste de Validação Cenário 1 Pré-condições Ambiente disponível para testes. Registros com Centro de Distribuição cadastrados. Passos Acessar o relatório. Realizar consulta de registros. Validar a informação apresentada. Resultado Esperado Valor exibido corretamente conforme a regra de negócio vigente. Cenário 2 Pré-condições Dados disponíveis no sistema de origem. Passos Comparar informação da origem com o relatório. Validar registros amostrais. Resultado Esperado Não existir divergência entre origem e relatório. Cenário 3 Pré-condições Ambiente QA contendo histórico das alterações descartadas. Passos Validar estrutura do relatório. Verificar se as colunas descartadas não foram promovidas. Resultado Esperado As colunas descartadas permanecem ausentes da solução final. ❌ Cenários de Teste de Rejeição Cenário 1 Quando a coluna Centro de Distribuição apresentar valor divergente da regra definida Então a implementação deverá ser rejeitada. Cenário 2 Quando as colunas descartadas do incidente 779404 forem disponibilizadas novamente Então a implementação deverá ser rejeitada. Cenário 3 Quando a correção impactar negativamente a visualização de outros dados do relatório Então a implementação deverá ser rejeitada. 🔄 Cenários de Teste de Regressão Cenário 1 Validar a execução normal do relatório Mapa de Fabricação/Expedição. Cenário 2 Validar exportação para Excel sem perda de informações. Cenário 3 Validar filtros existentes do relatório. Cenário 4 Validar carregamento e consulta dos demais campos do relatório. Cenário 5 Validar que não houve impacto em integrações já existentes entre os sistemas envolvidos. 🧭 Sugestão de Cutover Comunicação Informar usuários sobre a correção realizada no relatório. Governança Registrar a alteração por meio do fluxo formal de solicitação. Validação Executar testes integrados e validação com usuários-chave. Produção Publicar a correção após aprovação dos testes. Pós-implantação Monitorar consultas realizadas no relatório e registrar eventuais divergências identificadas. 📈 Score (GUT) Critério NotaGravidade 4 Urgência 4 Tendência 4 Resultado GUT 64 (4 × 4 × 4) Classificação Alta Prioridade Justificativa: a divergência afeta a confiabilidade das informações de negócio, já gerou incidentes anteriormente e tende a continuar gerando retrabalho e inconsistências caso não seja corrigida. | S21: 6 | T21: =_xlfn.XLOOKUP(S21,Tabela4[Horas],Tabela4[Pontos],,1) | U21: ENS-10762 | V21: ENS-10763 | W21: ENS-10764 | Y21: =HYPERLINK("https://tkebrasil.atlassian.net/browse/" & U21,U21) | Z21: =HYPERLINK("https://tkebrasil.atlassian.net/browse/" & V21,V21) | AA21: =HYPERLINK("https://tkebrasil.atlassian.net/browse/" & W21,W21) | AC21: X | AD21: BL
